Workbook

Sheet Scores
A1: Date | B1: Member | C1: Subject | D1: Book | E1: Correct | F1: Total | G1: % | H1: Notes | J1: ← Add one row per practice attempt. Pick Member/Subject/Book from the dropdowns; type Correct & Total.
A2: 46186 | B2: You | C2: Number Series | D2: Pilot Aptitude Test Workbook | E2: 14 | F2: 20 | G2: =IFERROR(E2/F2,"")
A3: 46192 | B3: You | C3: Number Series | D3: Pilot Aptitude Test Workbook | E3: 17 | F3: 20 | G3: =IFERROR(E3/F3,"")
A4: 46192 | B4: You | C4: Figure / Picture Series | D4: Pilot Aptitude Test Workbook | E4: 16 | F4: 20 | G4: =IFERROR(E4/F4,"")
A5: 46192 | B5: You | C5: Shape Scanning | D5: Pilot Aptitude Test Workbook | E5: 9 | F5: 20 | G5: =IFERROR(E5/F5,"")
A6: 46192 | B6: You | C6: Aircraft / Spatial Rotation | D6: Pilot Aptitude Test Workbook | E6: 15 | F6: 20 | G6: =IFERROR(E6/F6,"")
A7: 46186 | B7: Friend A | C7: Number Series | D7: Pilot Aptitude Test Workbook | E7: 12 | F7: 20 | G7: =IFERROR(E7/F7,"")
A8: 46192 | B8: Friend A | C8: Number Series | D8: Pilot Aptitude Test Workbook | E8: 13 | F8: 20 | G8: =IFERROR(E8/F8,"")
A9: 46192 | B9: Friend A | C9: Figure / Picture Series | D9: Pilot Aptitude Test Workbook | E9: 11 | F9: 20 | G9: =IFERROR(E9/F9,"")
A10: 46192 | B10: Friend A | C10: Shape Scanning | D10: Pilot Aptitude Test Workbook | E10: 8 | F10: 20 | G10: =IFERROR(E10/F10,"")
A11: 46192 | B11: Friend A | C11: Aircraft / Spatial Rotation | D11: Pilot Aptitude Test Workbook | E11: 10 | F11: 20 | G11: =IFERROR(E11/F11,"")
A12: 46192 | B12: Friend B | C12: Number Series | D12: Pilot Aptitude Test Workbook | E12: 18 | F12: 20 | G12: =IFERROR(E12/F12,"")
A13: 46192 | B13: Friend B | C13: Figure / Picture Series | D13: Pilot Aptitude Test Workbook | E13: 17 | F13: 20 | G13: =IFERROR(E13/F13,"")
... A15: 46192 | B15: Friend B | C15: Aircraft / Spatial Rotation | D15: Pilot Aptitude Test Workbook | E15: 16 | F15: 20 | G15: =IFERROR(E15/F15,"")
G16: =IFERROR(E16/F16,"")
G17: =IFERROR(E17/F17,"")
G18: =IFERROR(E18/F18,"")
G19: =IFERROR(E19/F19,"")
G20: =IFERROR(E20/F20,"")
G21: =IFERROR(E21/F21,"")
G22: =IFERROR(E22/F22,"")
G23: =IFERROR(E23/F23,"")
G24: =IFERROR(E24/F24,"")
G25: =IFERROR(E25/F25,"")
G26: =IFERROR(E26/F26,"")
G27: =IFERROR(E27/F27,"")
... G1001: =IFERROR(E1001/F1001,"")

Sheet Scoreboard
A1: Member \ Subject | B1: =IFERROR(Config!C2,"") | C1: =IFERROR(Config!C3,"") | D1: =IFERROR(Config!C4,"") | E1: =IFERROR(Config!C5,"") | F1: =IFERROR(Config!C6,"") | G1: =IFERROR(Config!C7,"") | H1: =IFERROR(Config!C8,"") | I1: =IFERROR(Config!C9,"") | J1: =IFERROR(Config!C10,"") | K1: =IFERROR(Config!C11,"") | L1: =IFERROR(Config!C12,"") | M1: =IFERROR(Config!C13,"") | N1: =IFERROR(Config!C14,"") | O1: =IFERROR(Config!C15,"") | P1: =IFERROR(Config!C16,"") | Q1: =IFERROR(Config!C17,"") | R1: =IFERROR(Config!C18,"") | S1: =IFERROR(Config!C19,"") | T1: =IFERROR(Config!C20,"") | U1: =IFERROR(Config!C21,"") | V1: =IFERROR(Config!C22,"") | W1: =IFERROR(Config!C23,"") | X1: =IFERROR(Config!C24,"") | Y1: =IFERROR(Config!C25,"") | Z1: =IFERROR(Config!C26,"") | AA1: =IFERROR(Config!C27,"") | AB1: =IFERROR(Config!C28,"") | AC1: =IFERROR(Config!C29,"") | AD1: =IFERROR(Config!C30,"") | AE1: =IFERROR(Config!C31,"") | AF1: Overall %
A2: =IFERROR(Config!A2,"") | B2: =IF(OR($A2="",B$1=""),"",IFERROR(AVERAGEIFS(Scores!$G$2:$G$1001,Scores!$B$2:$B$1001,$A2,Scores!$C$2:$C$1001,B$1,Scores!$A$2:$A$1001,MAXIFS(Scores!$A$2:$A$1001,Scores!$B$2:$B$1001,$A2,Scores!$C$2:$C$1001,B$1)),"")) | C2: =IF(OR($A2="",C$1=""),"",IFERROR(AVERAGEIFS(Scores!$G$2:$G$1001,Scores!$B$2:$B$1001,$A2,Scores!$C$2:$C$1001,C$1,Scores!$A$2:$A$1001,MAXIFS(Scores!$A$2:$A$1001,Scores!$B$2:$B$1001,$A2,Scores!$C$2:$C$1001,C$1)),"")) | D2: =IF(OR($A2="",D$1=""),"",IFERROR(AVERAGEIFS(Scores!$G$2:$G$1001,Scores!$B$2:$B$1001,$A2,Scores!$C$2:$C$1001,D$1,Scores!$A$2:$A$1001,MAXIFS(Scores!$A$2:$A$1001,Scores!$B$2:$B$1001,$A2,Scores!$C$2:$C$1001,D$1)),"")) | E2: =IF(OR($A2="",E$1=""),"",IFERROR(AVERAGEIFS(Scores!$G$2:$G$1001,Scores!$B$2:$B$1001,$A2,Scores!$C$2:$C$1001,E$1,Scores!$A$2:$A$1001,MAXIFS(Scores!$A$2:$A$1001,Scores!$B$2:$B$1001,$A2,Scores!$C$2:$C$1001,E$1)),"")) | F2: =IF(OR($A2="",F$1=""),"",IFERROR(AVERAGEIFS(Scores!$G$2:$G$1001,Scores!$B$2:$B$1001,$A2,Scores!$C$2:$C$1001,F$1,Scores!$A$2:$A$1001,MAXIFS(Scores!$A$2:$A$1001,Scores!$B$2:$B$1001,$A2,Scores!$C$2:$C$1001,F$1)),"")) | G2: =IF(OR($A2="",G$1=""),"",IFERROR(AVERAGEIFS(Scores!$G$2:$G$1001,Scores!$B$2:$B$1001,$A2,Scores!$C$2:$C$1001,G$1,Scores!$A$2:$A$1001,MAXIFS(Scores!$A$2:$A$1001,Scores!$B$2:$B$1001,$A2,Scores!$C$2:$C$1001,G$1)),"")) | H2: =IF(OR($A2="",H$1=""),"",IFERROR(AVERAGEIFS(Scores!$G$2:$G$1001,Scores!$B$2:$B$1001,$A2,Scores!$C$2:$C$1001,H$1,Scores!$A$2:$A$1001,MAXIFS(Scores!$A$2:$A$1001,Scores!$B$2:$B$1001,$A2,Scores!$C$2:$C$1001,H$1)),"")) | I2: =IF(OR($A2="",I$1=""),"",IFERROR(AVERAGEIFS(Scores!$G$2:$G$1001,Scores!$B$2:$B$1001,$A2,Scores!$C$2:$C$1001,I$1,Scores!$A$2:$A$1001,MAXIFS(Scores!$A$2:$A$1001,Scores!$B$2:$B$1001,$A2,Scores!$C$2:$C$1001,I$1)),"")) | ... AE2: =IF(OR($A2="",AE$1=""),"",IFERROR(AVERAGEIFS(Scores!$G$2:$G$1001,Scores!$B$2:$B$1001,$A2,Scores!$C$2:$C$1001,AE$1,Scores!$A$2:$A$1001,MAXIFS(Scores!$A$2:$A$1001,Scores!$B$2:$B$1001,$A2,Scores!$C$2:$C$1001,AE$1)),"")) | AF2: =IF($A2="","",IFERROR(AVERAGE(B2:AE2),""))
A3: =IFERROR(Config!A3,"") | B3: =IF(OR($A3="",B$1=""),"",IFERROR(AVERAGEIFS(Scores!$G$2:$G$1001,Scores!$B$2:$B$1001,$A3,Scores!$C$2:$C$1001,B$1,Scores!$A$2:$A$1001,MAXIFS(Scores!$A$2:$A$1001,Scores!$B$2:$B$1001,$A3,Scores!$C$2:$C$1001,B$1)),"")) | C3: =IF(OR($A3="",C$1=""),"",IFERROR(AVERAGEIFS(Scores!$G$2:$G$1001,Scores!$B$2:$B$1001,$A3,Scores!$C$2:$C$1001,C$1,Scores!$A$2:$A$1001,MAXIFS(Scores!$A$2:$A$1001,Scores!$B$2:$B$1001,$A3,Scores!$C$2:$C$1001,C$1)),"")) | D3: =IF(OR($A3="",D$1=""),"",IFERROR(AVERAGEIFS(Scores!$G$2:$G$1001,Scores!$B$2:$B$1001,$A3,Scores!$C$2:$C$1001,D$1,Scores!$A$2:$A$1001,MAXIFS(Scores!$A$2:$A$1001,Scores!$B$2:$B$1001,$A3,Scores!$C$2:$C$1001,D$1)),"")) | E3: =IF(OR($A3="",E$1=""),"",IFERROR(AVERAGEIFS(Scores!$G$2:$G$1001,Scores!$B$2:$B$1001,$A3,Scores!$C$2:$C$1001,E$1,Scores!$A$2:$A$1001,MAXIFS(Scores!$A$2:$A$1001,Scores!$B$2:$B$1001,$A3,Scores!$C$2:$C$1001,E$1)),"")) | F3: =IF(OR($A3="",F$1=""),"",IFERROR(AVERAGEIFS(Scores!$G$2:$G$1001,Scores!$B$2:$B$1001,$A3,Scores!$C$2:$C$1001,F$1,Scores!$A$2:$A$1001,MAXIFS(Scores!$A$2:$A$1001,Scores!$B$2:$B$1001,$A3,Scores!$C$2:$C$1001,F$1)),"")) | G3: =IF(OR($A3="",G$1=""),"",IFERROR(AVERAGEIFS(Scores!$G$2:$G$1001,Scores!$B$2:$B$1001,$A3,Scores!$C$2:$C$1001,G$1,Scores!$A$2:$A$1001,MAXIFS(Scores!$A$2:$A$1001,Scores!$B$2:$B$1001,$A3,Scores!$C$2:$C$1001,G$1)),"")) | H3: =IF(OR($A3="",H$1=""),"",IFERROR(AVERAGEIFS(Scores!$G$2:$G$1001,Scores!$B$2:$B$1001,$A3,Scores!$C$2:$C$1001,H$1,Scores!$A$2:$A$1001,MAXIFS(Scores!$A$2:$A$1001,Scores!$B$2:$B$1001,$A3,Scores!$C$2:$C$1001,H$1)),"")) | I3: =IF(OR($A3="",I$1=""),"",IFERROR(AVERAGEIFS(Scores!$G$2:$G$1001,Scores!$B$2:$B$1001,$A3,Scores!$C$2:$C$1001,I$1,Scores!$A$2:$A$1001,MAXIFS(Scores!$A$2:$A$1001,Scores!$B$2:$B$1001,$A3,Scores!$C$2:$C$1001,I$1)),"")) | ... AE3: =IF(OR($A3="",AE$1=""),"",IFERROR(AVERAGEIFS(Scores!$G$2:$G$1001,Scores!$B$2:$B$1001,$A3,Scores!$C$2:$C$1001,AE$1,Scores!$A$2:$A$1001,MAXIFS(Scores!$A$2:$A$1001,Scores!$B$2:$B$1001,$A3,Scores!$C$2:$C$1001,AE$1)),"")) | AF3: =IF($A3="","",IFERROR(AVERAGE(B3:AE3),""))
A4: =IFERROR(Config!A4,"") | B4: =IF(OR($A4="",B$1=""),"",IFERROR(AVERAGEIFS(Scores!$G$2:$G$1001,Scores!$B$2:$B$1001,$A4,Scores!$C$2:$C$1001,B$1,Scores!$A$2:$A$1001,MAXIFS(Scores!$A$2:$A$1001,Scores!$B$2:$B$1001,$A4,Scores!$C$2:$C$1001,B$1)),"")) | C4: =IF(OR($A4="",C$1=""),"",IFERROR(AVERAGEIFS(Scores!$G$2:$G$1001,Scores!$B$2:$B$1001,$A4,Scores!$C$2:$C$1001,C$1,Scores!$A$2:$A$1001,MAXIFS(Scores!$A$2:$A$1001,Scores!$B$2:$B$1001,$A4,Scores!$C$2:$C$1001,C$1)),"")) | D4: =IF(OR($A4="",D$1=""),"",IFERROR(AVERAGEIFS(Scores!$G$2:$G$1001,Scores!$B$2:$B$1001,$A4,Scores!$C$2:$C$1001,D$1,Scores!$A$2:$A$1001,MAXIFS(Scores!$A$2:$A$1001,Scores!$B$2:$B$1001,$A4,Scores!$C$2:$C$1001,D$1)),"")) | E4: =IF(OR($A4="",E$1=""),"",IFERROR(AVERAGEIFS(Scores!$G$2:$G$1001,Scores!$B$2:$B$1001,$A4,Scores!$C$2:$C$1001,E$1,Scores!$A$2:$A$1001,MAXIFS(Scores!$A$2:$A$1001,Scores!$B$2:$B$1001,$A4,Scores!$C$2:$C$1001,E$1)),"")) | F4: =IF(OR($A4="",F$1=""),"",IFERROR(AVERAGEIFS(Scores!$G$2:$G$1001,Scores!$B$2:$B$1001,$A4,Scores!$C$2:$C$1001,F$1,Scores!$A$2:$A$1001,MAXIFS(Scores!$A$2:$A$1001,Scores!$B$2:$B$1001,$A4,Scores!$C$2:$C$1001,F$1)),"")) | G4: =IF(OR($A4="",G$1=""),"",IFERROR(AVERAGEIFS(Scores!$G$2:$G$1001,Scores!$B$2:$B$1001,$A4,Scores!$C$2:$C$1001,G$1,Scores!$A$2:$A$1001,MAXIFS(Scores!$A$2:$A$1001,Scores!$B$2:$B$1001,$A4,Scores!$C$2:$C$1001,G$1)),"")) | H4: =IF(OR($A4="",H$1=""),"",IFERROR(AVERAGEIFS(Scores!$G$2:$G$1001,Scores!$B$2:$B$1001,$A4,Scores!$C$2:$C$1001,H$1,Scores!$A$2:$A$1001,MAXIFS(Scores!$A$2:$A$1001,Scores!$B$2:$B$1001,$A4,Scores!$C$2:$C$1001,H$1)),"")) | I4: =IF(OR($A4="",I$1=""),"",IFERROR(AVERAGEIFS(Scores!$G$2:$G$1001,Scores!$B$2:$B$1001,$A4,Scores!$C$2:$C$1001,I$1,Scores!$A$2:$A$1001,MAXIFS(Scores!$A$2:$A$1001,Scores!$B$2:$B$1001,$A4,Scores!$C$2:$C$1001,I$1)),"")) | ... AE4: =IF(OR($A4="",AE$1=""),"",IFERROR(AVERAGEIFS(Scores!$G$2:$G$1001,Scores!$B$2:$B$1001,$A4,Scores!$C$2:$C$1001,AE$1,Scores!$A$2:$A$1001,MAXIFS(Scores!$A$2:$A$1001,Scores!$B$2:$B$1001,$A4,Scores!$C$2:$C$1001,AE$1)),"")) | AF4: =IF($A4="","",IFERROR(AVERAGE(B4:AE4),""))
A5: =IFERROR(Config!A5,"") | B5: =IF(OR($A5="",B$1=""),"",IFERROR(AVERAGEIFS(Scores!$G$2:$G$1001,Scores!$B$2:$B$1001,$A5,Scores!$C$2:$C$1001,B$1,Scores!$A$2:$A$1001,MAXIFS(Scores!$A$2:$A$1001,Scores!$B$2:$B$1001,$A5,Scores!$C$2:$C$1001,B$1)),"")) | C5: =IF(OR($A5="",C$1=""),"",IFERROR(AVERAGEIFS(Scores!$G$2:$G$1001,Scores!$B$2:$B$1001,$A5,Scores!$C$2:$C$1001,C$1,Scores!$A$2:$A$1001,MAXIFS(Scores!$A$2:$A$1001,Scores!$B$2:$B$1001,$A5,Scores!$C$2:$C$1001,C$1)),"")) | D5: =IF(OR($A5="",D$1=""),"",IFERROR(AVERAGEIFS(Scores!$G$2:$G$1001,Scores!$B$2:$B$1001,$A5,Scores!$C$2:$C$1001,D$1,Scores!$A$2:$A$1001,MAXIFS(Scores!$A$2:$A$1001,Scores!$B$2:$B$1001,$A5,Scores!$C$2:$C$1001,D$1)),"")) | E5: =IF(OR($A5="",E$1=""),"",IFERROR(AVERAGEIFS(Scores!$G$2:$G$1001,Scores!$B$2:$B$1001,$A5,Scores!$C$2:$C$1001,E$1,Scores!$A$2:$A$1001,MAXIFS(Scores!$A$2:$A$1001,Scores!$B$2:$B$1001,$A5,Scores!$C$2:$C$1001,E$1)),"")) | F5: =IF(OR($A5="",F$1=""),"",IFERROR(AVERAGEIFS(Scores!$G$2:$G$1001,Scores!$B$2:$B$1001,$A5,Scores!$C$2:$C$1001,F$1,Scores!$A$2:$A$1001,MAXIFS(Scores!$A$2:$A$1001,Scores!$B$2:$B$1001,$A5,Scores!$C$2:$C$1001,F$1)),"")) | G5: =IF(OR($A5="",G$1=""),"",IFERROR(AVERAGEIFS(Scores!$G$2:$G$1001,Scores!$B$2:$B$1001,$A5,Scores!$C$2:$C$1001,G$1,Scores!$A$2:$A$1001,MAXIFS(Scores!$A$2:$A$1001,Scores!$B$2:$B$1001,$A5,Scores!$C$2:$C$1001,G$1)),"")) | H5: =IF(OR($A5="",H$1=""),"",IFERROR(AVERAGEIFS(Scores!$G$2:$G$1001,Scores!$B$2:$B$1001,$A5,Scores!$C$2:$C$1001,H$1,Scores!$A$2:$A$1001,MAXIFS(Scores!$A$2:$A$1001,Scores!$B$2:$B$1001,$A5,Scores!$C$2:$C$1001,H$1)),"")) | I5: =IF(OR($A5="",I$1=""),"",IFERROR(AVERAGEIFS(Scores!$G$2:$G$1001,Scores!$B$2:$B$1001,$A5,Scores!$C$2:$C$1001,I$1,Scores!$A$2:$A$1001,MAXIFS(Scores!$A$2:$A$1001,Scores!$B$2:$B$1001,$A5,Scores!$C$2:$C$1001,I$1)),"")) | ... AE5: =IF(OR($A5="",AE$1=""),"",IFERROR(AVERAGEIFS(Scores!$G$2:$G$1001,Scores!$B$2:$B$1001,$A5,Scores!$C$2:$C$1001,AE$1,Scores!$A$2:$A$1001,MAXIFS(Scores!$A$2:$A$1001,Scores!$B$2:$B$1001,$A5,Scores!$C$2:$C$1001,AE$1)),"")) | AF5: =IF($A5="","",IFERROR(AVERAGE(B5:AE5),""))
A6: =IFERROR(Config!A6,"") | B6: =IF(OR($A6="",B$1=""),"",IFERROR(AVERAGEIFS(Scores!$G$2:$G$1001,Scores!$B$2:$B$1001,$A6,Scores!$C$2:$C$1001,B$1,Scores!$A$2:$A$1001,MAXIFS(Scores!$A$2:$A$1001,Scores!$B$2:$B$1001,$A6,Scores!$C$2:$C$1001,B$1)),"")) | C6: =IF(OR($A6="",C$1=""),"",IFERROR(AVERAGEIFS(Scores!$G$2:$G$1001,Scores!$B$2:$B$1001,$A6,Scores!$C$2:$C$1001,C$1,Scores!$A$2:$A$1001,MAXIFS(Scores!$A$2:$A$1001,Scores!$B$2:$B$1001,$A6,Scores!$C$2:$C$1001,C$1)),"")) | D6: =IF(OR($A6="",D$1=""),"",IFERROR(AVERAGEIFS(Scores!$G$2:$G$1001,Scores!$B$2:$B$1001,$A6,Scores!$C$2:$C$1001,D$1,Scores!$A$2:$A$1001,MAXIFS(Scores!$A$2:$A$1001,Scores!$B$2:$B$1001,$A6,Scores!$C$2:$C$1001,D$1)),"")) | E6: =IF(OR($A6="",E$1=""),"",IFERROR(AVERAGEIFS(Scores!$G$2:$G$1001,Scores!$B$2:$B$1001,$A6,Scores!$C$2:$C$1001,E$1,Scores!$A$2:$A$1001,MAXIFS(Scores!$A$2:$A$1001,Scores!$B$2:$B$1001,$A6,Scores!$C$2:$C$1001,E$1)),"")) | F6: =IF(OR($A6="",F$1=""),"",IFERROR(AVERAGEIFS(Scores!$G$2:$G$1001,Scores!$B$2:$B$1001,$A6,Scores!$C$2:$C$1001,F$1,Scores!$A$2:$A$1001,MAXIFS(Scores!$A$2:$A$1001,Scores!$B$2:$B$1001,$A6,Scores!$C$2:$C$1001,F$1)),"")) | G6: =IF(OR($A6="",G$1=""),"",IFERROR(AVERAGEIFS(Scores!$G$2:$G$1001,Scores!$B$2:$B$1001,$A6,Scores!$C$2:$C$1001,G$1,Scores!$A$2:$A$1001,MAXIFS(Scores!$A$2:$A$1001,Scores!$B$2:$B$1001,$A6,Scores!$C$2:$C$1001,G$1)),"")) | H6: =IF(OR($A6="",H$1=""),"",IFERROR(AVERAGEIFS(Scores!$G$2:$G$1001,Scores!$B$2:$B$1001,$A6,Scores!$C$2:$C$1001,H$1,Scores!$A$2:$A$1001,MAXIFS(Scores!$A$2:$A$1001,Scores!$B$2:$B$1001,$A6,Scores!$C$2:$C$1001,H$1)),"")) | I6: =IF(OR($A6="",I$1=""),"",IFERROR(AVERAGEIFS(Scores!$G$2:$G$1001,Scores!$B$2:$B$1001,$A6,Scores!$C$2:$C$1001,I$1,Scores!$A$2:$A$1001,MAXIFS(Scores!$A$2:$A$1001,Scores!$B$2:$B$1001,$A6,Scores!$C$2:$C$1001,I$1)),"")) | ... AE6: =IF(OR($A6="",AE$1=""),"",IFERROR(AVERAGEIFS(Scores!$G$2:$G$1001,Scores!$B$2:$B$1001,$A6,Scores!$C$2:$C$1001,AE$1,Scores!$A$2:$A$1001,MAXIFS(Scores!$A$2:$A$1001,Scores!$B$2:$B$1001,$A6,Scores!$C$2:$C$1001,AE$1)),"")) | AF6: =IF($A6="","",IFERROR(AVERAGE(B6:AE6),""))
A7: =IFERROR(Config!A7,"") | B7: =IF(OR($A7="",B$1=""),"",IFERROR(AVERAGEIFS(Scores!$G$2:$G$1001,Scores!$B$2:$B$1001,$A7,Scores!$C$2:$C$1001,B$1,Scores!$A$2:$A$1001,MAXIFS(Scores!$A$2:$A$1001,Scores!$B$2:$B$1001,$A7,Scores!$C$2:$C$1001,B$1)),"")) | C7: =IF(OR($A7="",C$1=""),"",IFERROR(AVERAGEIFS(Scores!$G$2:$G$1001,Scores!$B$2:$B$1001,$A7,Scores!$C$2:$C$1001,C$1,Scores!$A$2:$A$1001,MAXIFS(Scores!$A$2:$A$1001,Scores!$B$2:$B$1001,$A7,Scores!$C$2:$C$1001,C$1)),"")) | D7: =IF(OR($A7="",D$1=""),"",IFERROR(AVERAGEIFS(Scores!$G$2:$G$1001,Scores!$B$2:$B$1001,$A7,Scores!$C$2:$C$1001,D$1,Scores!$A$2:$A$1001,MAXIFS(Scores!$A$2:$A$1001,Scores!$B$2:$B$1001,$A7,Scores!$C$2:$C$1001,D$1)),"")) | E7: =IF(OR($A7="",E$1=""),"",IFERROR(AVERAGEIFS(Scores!$G$2:$G$1001,Scores!$B$2:$B$1001,$A7,Scores!$C$2:$C$1001,E$1,Scores!$A$2:$A$1001,MAXIFS(Scores!$A$2:$A$1001,Scores!$B$2:$B$1001,$A7,Scores!$C$2:$C$1001,E$1)),"")) | F7: =IF(OR($A7="",F$1=""),"",IFERROR(AVERAGEIFS(Scores!$G$2:$G$1001,Scores!$B$2:$B$1001,$A7,Scores!$C$2:$C$1001,F$1,Scores!$A$2:$A$1001,MAXIFS(Scores!$A$2:$A$1001,Scores!$B$2:$B$1001,$A7,Scores!$C$2:$C$1001,F$1)),"")) | G7: =IF(OR($A7="",G$1=""),"",IFERROR(AVERAGEIFS(Scores!$G$2:$G$1001,Scores!$B$2:$B$1001,$A7,Scores!$C$2:$C$1001,G$1,Scores!$A$2:$A$1001,MAXIFS(Scores!$A$2:$A$1001,Scores!$B$2:$B$1001,$A7,Scores!$C$2:$C$1001,G$1)),"")) | H7: =IF(OR($A7="",H$1=""),"",IFERROR(AVERAGEIFS(Scores!$G$2:$G$1001,Scores!$B$2:$B$1001,$A7,Scores!$C$2:$C$1001,H$1,Scores!$A$2:$A$1001,MAXIFS(Scores!$A$2:$A$1001,Scores!$B$2:$B$1001,$A7,Scores!$C$2:$C$1001,H$1)),"")) | I7: =IF(OR($A7="",I$1=""),"",IFERROR(AVERAGEIFS(Scores!$G$2:$G$1001,Scores!$B$2:$B$1001,$A7,Scores!$C$2:$C$1001,I$1,Scores!$A$2:$A$1001,MAXIFS(Scores!$A$2:$A$1001,Scores!$B$2:$B$1001,$A7,Scores!$C$2:$C$1001,I$1)),"")) | ... AE7: =IF(OR($A7="",AE$1=""),"",IFERROR(AVERAGEIFS(Scores!$G$2:$G$1001,Scores!$B$2:$B$1001,$A7,Scores!$C$2:$C$1001,AE$1,Scores!$A$2:$A$1001,MAXIFS(Scores!$A$2:$A$1001,Scores!$B$2:$B$1001,$A7,Scores!$C$2:$C$1001,AE$1)),"")) | AF7: =IF($A7="","",IFERROR(AVERAGE(B7:AE7),""))
A8: =IFERROR(Config!A8,"") | B8: =IF(OR($A8="",B$1=""),"",IFERROR(AVERAGEIFS(Scores!$G$2:$G$1001,Scores!$B$2:$B$1001,$A8,Scores!$C$2:$C$1001,B$1,Scores!$A$2:$A$1001,MAXIFS(Scores!$A$2:$A$1001,Scores!$B$2:$B$1001,$A8,Scores!$C$2:$C$1001,B$1)),"")) | C8: =IF(OR($A8="",C$1=""),"",IFERROR(AVERAGEIFS(Scores!$G$2:$G$1001,Scores!$B$2:$B$1001,$A8,Scores!$C$2:$C$1001,C$1,Scores!$A$2:$A$1001,MAXIFS(Scores!$A$2:$A$1001,Scores!$B$2:$B$1001,$A8,Scores!$C$2:$C$1001,C$1)),"")) | D8: =IF(OR($A8="",D$1=""),"",IFERROR(AVERAGEIFS(Scores!$G$2:$G$1001,Scores!$B$2:$B$1001,$A8,Scores!$C$2:$C$1001,D$1,Scores!$A$2:$A$1001,MAXIFS(Scores!$A$2:$A$1001,Scores!$B$2:$B$1001,$A8,Scores!$C$2:$C$1001,D$1)),"")) | E8: =IF(OR($A8="",E$1=""),"",IFERROR(AVERAGEIFS(Scores!$G$2:$G$1001,Scores!$B$2:$B$1001,$A8,Scores!$C$2:$C$1001,E$1,Scores!$A$2:$A$1001,MAXIFS(Scores!$A$2:$A$1001,Scores!$B$2:$B$1001,$A8,Scores!$C$2:$C$1001,E$1)),"")) | F8: =IF(OR($A8="",F$1=""),"",IFERROR(AVERAGEIFS(Scores!$G$2:$G$1001,Scores!$B$2:$B$1001,$A8,Scores!$C$2:$C$1001,F$1,Scores!$A$2:$A$1001,MAXIFS(Scores!$A$2:$A$1001,Scores!$B$2:$B$1001,$A8,Scores!$C$2:$C$1001,F$1)),"")) | G8: =IF(OR($A8="",G$1=""),"",IFERROR(AVERAGEIFS(Scores!$G$2:$G$1001,Scores!$B$2:$B$1001,$A8,Scores!$C$2:$C$1001,G$1,Scores!$A$2:$A$1001,MAXIFS(Scores!$A$2:$A$1001,Scores!$B$2:$B$1001,$A8,Scores!$C$2:$C$1001,G$1)),"")) | H8: =IF(OR($A8="",H$1=""),"",IFERROR(AVERAGEIFS(Scores!$G$2:$G$1001,Scores!$B$2:$B$1001,$A8,Scores!$C$2:$C$1001,H$1,Scores!$A$2:$A$1001,MAXIFS(Scores!$A$2:$A$1001,Scores!$B$2:$B$1001,$A8,Scores!$C$2:$C$1001,H$1)),"")) | I8: =IF(OR($A8="",I$1=""),"",IFERROR(AVERAGEIFS(Scores!$G$2:$G$1001,Scores!$B$2:$B$1001,$A8,Scores!$C$2:$C$1001,I$1,Scores!$A$2:$A$1001,MAXIFS(Scores!$A$2:$A$1001,Scores!$B$2:$B$1001,$A8,Scores!$C$2:$C$1001,I$1)),"")) | ... AE8: =IF(OR($A8="",AE$1=""),"",IFERROR(AVERAGEIFS(Scores!$G$2:$G$1001,Scores!$B$2:$B$1001,$A8,Scores!$C$2:$C$1001,AE$1,Scores!$A$2:$A$1001,MAXIFS(Scores!$A$2:$A$1001,Scores!$B$2:$B$1001,$A8,Scores!$C$2:$C$1001,AE$1)),"")) | AF8: =IF($A8="","",IFERROR(AVERAGE(B8:AE8),""))
A9: =IFERROR(Config!A9,"") | B9: =IF(OR($A9="",B$1=""),"",IFERROR(AVERAGEIFS(Scores!$G$2:$G$1001,Scores!$B$2:$B$1001,$A9,Scores!$C$2:$C$1001,B$1,Scores!$A$2:$A$1001,MAXIFS(Scores!$A$2:$A$1001,Scores!$B$2:$B$1001,$A9,Scores!$C$2:$C$1001,B$1)),"")) | C9: =IF(OR($A9="",C$1=""),"",IFERROR(AVERAGEIFS(Scores!$G$2:$G$1001,Scores!$B$2:$B$1001,$A9,Scores!$C$2:$C$1001,C$1,Scores!$A$2:$A$1001,MAXIFS(Scores!$A$2:$A$1001,Scores!$B$2:$B$1001,$A9,Scores!$C$2:$C$1001,C$1)),"")) | D9: =IF(OR($A9="",D$1=""),"",IFERROR(AVERAGEIFS(Scores!$G$2:$G$1001,Scores!$B$2:$B$1001,$A9,Scores!$C$2:$C$1001,D$1,Scores!$A$2:$A$1001,MAXIFS(Scores!$A$2:$A$1001,Scores!$B$2:$B$1001,$A9,Scores!$C$2:$C$1001,D$1)),"")) | E9: =IF(OR($A9="",E$1=""),"",IFERROR(AVERAGEIFS(Scores!$G$2:$G$1001,Scores!$B$2:$B$1001,$A9,Scores!$C$2:$C$1001,E$1,Scores!$A$2:$A$1001,MAXIFS(Scores!$A$2:$A$1001,Scores!$B$2:$B$1001,$A9,Scores!$C$2:$C$1001,E$1)),"")) | F9: =IF(OR($A9="",F$1=""),"",IFERROR(AVERAGEIFS(Scores!$G$2:$G$1001,Scores!$B$2:$B$1001,$A9,Scores!$C$2:$C$1001,F$1,Scores!$A$2:$A$1001,MAXIFS(Scores!$A$2:$A$1001,Scores!$B$2:$B$1001,$A9,Scores!$C$2:$C$1001,F$1)),"")) | G9: =IF(OR($A9="",G$1=""),"",IFERROR(AVERAGEIFS(Scores!$G$2:$G$1001,Scores!$B$2:$B$1001,$A9,Scores!$C$2:$C$1001,G$1,Scores!$A$2:$A$1001,MAXIFS(Scores!$A$2:$A$1001,Scores!$B$2:$B$1001,$A9,Scores!$C$2:$C$1001,G$1)),"")) | H9: =IF(OR($A9="",H$1=""),"",IFERROR(AVERAGEIFS(Scores!$G$2:$G$1001,Scores!$B$2:$B$1001,$A9,Scores!$C$2:$C$1001,H$1,Scores!$A$2:$A$1001,MAXIFS(Scores!$A$2:$A$1001,Scores!$B$2:$B$1001,$A9,Scores!$C$2:$C$1001,H$1)),"")) | I9: =IF(OR($A9="",I$1=""),"",IFERROR(AVERAGEIFS(Scores!$G$2:$G$1001,Scores!$B$2:$B$1001,$A9,Scores!$C$2:$C$1001,I$1,Scores!$A$2:$A$1001,MAXIFS(Scores!$A$2:$A$1001,Scores!$B$2:$B$1001,$A9,Scores!$C$2:$C$1001,I$1)),"")) | ... AE9: =IF(OR($A9="",AE$1=""),"",IFERROR(AVERAGEIFS(Scores!$G$2:$G$1001,Scores!$B$2:$B$1001,$A9,Scores!$C$2:$C$1001,AE$1,Scores!$A$2:$A$1001,MAXIFS(Scores!$A$2:$A$1001,Scores!$B$2:$B$1001,$A9,Scores!$C$2:$C$1001,AE$1)),"")) | AF9: =IF($A9="","",IFERROR(AVERAGE(B9:AE9),""))
A10: =IFERROR(Config!A10,"") | B10: =IF(OR($A10="",B$1=""),"",IFERROR(AVERAGEIFS(Scores!$G$2:$G$1001,Scores!$B$2:$B$1001,$A10,Scores!$C$2:$C$1001,B$1,Scores!$A$2:$A$1001,MAXIFS(Scores!$A$2:$A$1001,Scores!$B$2:$B$1001,$A10,Scores!$C$2:$C$1001,B$1)),"")) | C10: =IF(OR($A10="",C$1=""),"",IFERROR(AVERAGEIFS(Scores!$G$2:$G$1001,Scores!$B$2:$B$1001,$A10,Scores!$C$2:$C$1001,C$1,Scores!$A$2:$A$1001,MAXIFS(Scores!$A$2:$A$1001,Scores!$B$2:$B$1001,$A10,Scores!$C$2:$C$1001,C$1)),"")) | D10: =IF(OR($A10="",D$1=""),"",IFERROR(AVERAGEIFS(Scores!$G$2:$G$1001,Scores!$B$2:$B$1001,$A10,Scores!$C$2:$C$1001,D$1,Scores!$A$2:$A$1001,MAXIFS(Scores!$A$2:$A$1001,Scores!$B$2:$B$1001,$A10,Scores!$C$2:$C$1001,D$1)),"")) | E10: =IF(OR($A10="",E$1=""),"",IFERROR(AVERAGEIFS(Scores!$G$2:$G$1001,Scores!$B$2:$B$1001,$A10,Scores!$C$2:$C$1001,E$1,Scores!$A$2:$A$1001,MAXIFS(Scores!$A$2:$A$1001,Scores!$B$2:$B$1001,$A10,Scores!$C$2:$C$1001,E$1)),"")) | F10: =IF(OR($A10="",F$1=""),"",IFERROR(AVERAGEIFS(Scores!$G$2:$G$1001,Scores!$B$2:$B$1001,$A10,Scores!$C$2:$C$1001,F$1,Scores!$A$2:$A$1001,MAXIFS(Scores!$A$2:$A$1001,Scores!$B$2:$B$1001,$A10,Scores!$C$2:$C$1001,F$1)),"")) | G10: =IF(OR($A10="",G$1=""),"",IFERROR(AVERAGEIFS(Scores!$G$2:$G$1001,Scores!$B$2:$B$1001,$A10,Scores!$C$2:$C$1001,G$1,Scores!$A$2:$A$1001,MAXIFS(Scores!$A$2:$A$1001,Scores!$B$2:$B$1001,$A10,Scores!$C$2:$C$1001,G$1)),"")) | H10: =IF(OR($A10="",H$1=""),"",IFERROR(AVERAGEIFS(Scores!$G$2:$G$1001,Scores!$B$2:$B$1001,$A10,Scores!$C$2:$C$1001,H$1,Scores!$A$2:$A$1001,MAXIFS(Scores!$A$2:$A$1001,Scores!$B$2:$B$1001,$A10,Scores!$C$2:$C$1001,H$1)),"")) | I10: =IF(OR($A10="",I$1=""),"",IFERROR(AVERAGEIFS(Scores!$G$2:$G$1001,Scores!$B$2:$B$1001,$A10,Scores!$C$2:$C$1001,I$1,Scores!$A$2:$A$1001,MAXIFS(Scores!$A$2:$A$1001,Scores!$B$2:$B$1001,$A10,Scores!$C$2:$C$1001,I$1)),"")) | ... AE10: =IF(OR($A10="",AE$1=""),"",IFERROR(AVERAGEIFS(Scores!$G$2:$G$1001,Scores!$B$2:$B$1001,$A10,Scores!$C$2:$C$1001,AE$1,Scores!$A$2:$A$1001,MAXIFS(Scores!$A$2:$A$1001,Scores!$B$2:$B$1001,$A10,Scores!$C$2:$C$1001,AE$1)),"")) | AF10: =IF($A10="","",IFERROR(AVERAGE(B10:AE10),""))
A11: =IFERROR(Config!A11,"") | B11: =IF(OR($A11="",B$1=""),"",IFERROR(AVERAGEIFS(Scores!$G$2:$G$1001,Scores!$B$2:$B$1001,$A11,Scores!$C$2:$C$1001,B$1,Scores!$A$2:$A$1001,MAXIFS(Scores!$A$2:$A$1001,Scores!$B$2:$B$1001,$A11,Scores!$C$2:$C$1001,B$1)),"")) | C11: =IF(OR($A11="",C$1=""),"",IFERROR(AVERAGEIFS(Scores!$G$2:$G$1001,Scores!$B$2:$B$1001,$A11,Scores!$C$2:$C$1001,C$1,Scores!$A$2:$A$1001,MAXIFS(Scores!$A$2:$A$1001,Scores!$B$2:$B$1001,$A11,Scores!$C$2:$C$1001,C$1)),"")) | D11: =IF(OR($A11="",D$1=""),"",IFERROR(AVERAGEIFS(Scores!$G$2:$G$1001,Scores!$B$2:$B$1001,$A11,Scores!$C$2:$C$1001,D$1,Scores!$A$2:$A$1001,MAXIFS(Scores!$A$2:$A$1001,Scores!$B$2:$B$1001,$A11,Scores!$C$2:$C$1001,D$1)),"")) | E11: =IF(OR($A11="",E$1=""),"",IFERROR(AVERAGEIFS(Scores!$G$2:$G$1001,Scores!$B$2:$B$1001,$A11,Scores!$C$2:$C$1001,E$1,Scores!$A$2:$A$1001,MAXIFS(Scores!$A$2:$A$1001,Scores!$B$2:$B$1001,$A11,Scores!$C$2:$C$1001,E$1)),"")) | F11: =IF(OR($A11="",F$1=""),"",IFERROR(AVERAGEIFS(Scores!$G$2:$G$1001,Scores!$B$2:$B$1001,$A11,Scores!$C$2:$C$1001,F$1,Scores!$A$2:$A$1001,MAXIFS(Scores!$A$2:$A$1001,Scores!$B$2:$B$1001,$A11,Scores!$C$2:$C$1001,F$1)),"")) | G11: =IF(OR($A11="",G$1=""),"",IFERROR(AVERAGEIFS(Scores!$G$2:$G$1001,Scores!$B$2:$B$1001,$A11,Scores!$C$2:$C$1001,G$1,Scores!$A$2:$A$1001,MAXIFS(Scores!$A$2:$A$1001,Scores!$B$2:$B$1001,$A11,Scores!$C$2:$C$1001,G$1)),"")) | H11: =IF(OR($A11="",H$1=""),"",IFERROR(AVERAGEIFS(Scores!$G$2:$G$1001,Scores!$B$2:$B$1001,$A11,Scores!$C$2:$C$1001,H$1,Scores!$A$2:$A$1001,MAXIFS(Scores!$A$2:$A$1001,Scores!$B$2:$B$1001,$A11,Scores!$C$2:$C$1001,H$1)),"")) | I11: =IF(OR($A11="",I$1=""),"",IFERROR(AVERAGEIFS(Scores!$G$2:$G$1001,Scores!$B$2:$B$1001,$A11,Scores!$C$2:$C$1001,I$1,Scores!$A$2:$A$1001,MAXIFS(Scores!$A$2:$A$1001,Scores!$B$2:$B$1001,$A11,Scores!$C$2:$C$1001,I$1)),"")) | ... AE11: =IF(OR($A11="",AE$1=""),"",IFERROR(AVERAGEIFS(Scores!$G$2:$G$1001,Scores!$B$2:$B$1001,$A11,Scores!$C$2:$C$1001,AE$1,Scores!$A$2:$A$1001,MAXIFS(Scores!$A$2:$A$1001,Scores!$B$2:$B$1001,$A11,Scores!$C$2:$C$1001,AE$1)),"")) | AF11: =IF($A11="","",IFERROR(AVERAGE(B11:AE11),""))
A12: =IFERROR(Config!A12,"") | B12: =IF(OR($A12="",B$1=""),"",IFERROR(AVERAGEIFS(Scores!$G$2:$G$1001,Scores!$B$2:$B$1001,$A12,Scores!$C$2:$C$1001,B$1,Scores!$A$2:$A$1001,MAXIFS(Scores!$A$2:$A$1001,Scores!$B$2:$B$1001,$A12,Scores!$C$2:$C$1001,B$1)),"")) | C12: =IF(OR($A12="",C$1=""),"",IFERROR(AVERAGEIFS(Scores!$G$2:$G$1001,Scores!$B$2:$B$1001,$A12,Scores!$C$2:$C$1001,C$1,Scores!$A$2:$A$1001,MAXIFS(Scores!$A$2:$A$1001,Scores!$B$2:$B$1001,$A12,Scores!$C$2:$C$1001,C$1)),"")) | D12: =IF(OR($A12="",D$1=""),"",IFERROR(AVERAGEIFS(Scores!$G$2:$G$1001,Scores!$B$2:$B$1001,$A12,Scores!$C$2:$C$1001,D$1,Scores!$A$2:$A$1001,MAXIFS(Scores!$A$2:$A$1001,Scores!$B$2:$B$1001,$A12,Scores!$C$2:$C$1001,D$1)),"")) | E12: =IF(OR($A12="",E$1=""),"",IFERROR(AVERAGEIFS(Scores!$G$2:$G$1001,Scores!$B$2:$B$1001,$A12,Scores!$C$2:$C$1001,E$1,Scores!$A$2:$A$1001,MAXIFS(Scores!$A$2:$A$1001,Scores!$B$2:$B$1001,$A12,Scores!$C$2:$C$1001,E$1)),"")) | F12: =IF(OR($A12="",F$1=""),"",IFERROR(AVERAGEIFS(Scores!$G$2:$G$1001,Scores!$B$2:$B$1001,$A12,Scores!$C$2:$C$1001,F$1,Scores!$A$2:$A$1001,MAXIFS(Scores!$A$2:$A$1001,Scores!$B$2:$B$1001,$A12,Scores!$C$2:$C$1001,F$1)),"")) | G12: =IF(OR($A12="",G$1=""),"",IFERROR(AVERAGEIFS(Scores!$G$2:$G$1001,Scores!$B$2:$B$1001,$A12,Scores!$C$2:$C$1001,G$1,Scores!$A$2:$A$1001,MAXIFS(Scores!$A$2:$A$1001,Scores!$B$2:$B$1001,$A12,Scores!$C$2:$C$1001,G$1)),"")) | H12: =IF(OR($A12="",H$1=""),"",IFERROR(AVERAGEIFS(Scores!$G$2:$G$1001,Scores!$B$2:$B$1001,$A12,Scores!$C$2:$C$1001,H$1,Scores!$A$2:$A$1001,MAXIFS(Scores!$A$2:$A$1001,Scores!$B$2:$B$1001,$A12,Scores!$C$2:$C$1001,H$1)),"")) | I12: =IF(OR($A12="",I$1=""),"",IFERROR(AVERAGEIFS(Scores!$G$2:$G$1001,Scores!$B$2:$B$1001,$A12,Scores!$C$2:$C$1001,I$1,Scores!$A$2:$A$1001,MAXIFS(Scores!$A$2:$A$1001,Scores!$B$2:$B$1001,$A12,Scores!$C$2:$C$1001,I$1)),"")) | ... AE12: =IF(OR($A12="",AE$1=""),"",IFERROR(AVERAGEIFS(Scores!$G$2:$G$1001,Scores!$B$2:$B$1001,$A12,Scores!$C$2:$C$1001,AE$1,Scores!$A$2:$A$1001,MAXIFS(Scores!$A$2:$A$1001,Scores!$B$2:$B$1001,$A12,Scores!$C$2:$C$1001,AE$1)),"")) | AF12: =IF($A12="","",IFERROR(AVERAGE(B12:AE12),""))
A13: =IFERROR(Config!A13,"") | B13: =IF(OR($A13="",B$1=""),"",IFERROR(AVERAGEIFS(Scores!$G$2:$G$1001,Scores!$B$2:$B$1001,$A13,Scores!$C$2:$C$1001,B$1,Scores!$A$2:$A$1001,MAXIFS(Scores!$A$2:$A$1001,Scores!$B$2:$B$1001,$A13,Scores!$C$2:$C$1001,B$1)),"")) | C13: =IF(OR($A13="",C$1=""),"",IFERROR(AVERAGEIFS(Scores!$G$2:$G$1001,Scores!$B$2:$B$1001,$A13,Scores!$C$2:$C$1001,C$1,Scores!$A$2:$A$1001,MAXIFS(Scores!$A$2:$A$1001,Scores!$B$2:$B$1001,$A13,Scores!$C$2:$C$1001,C$1)),"")) | D13: =IF(OR($A13="",D$1=""),"",IFERROR(AVERAGEIFS(Scores!$G$2:$G$1001,Scores!$B$2:$B$1001,$A13,Scores!$C$2:$C$1001,D$1,Scores!$A$2:$A$1001,MAXIFS(Scores!$A$2:$A$1001,Scores!$B$2:$B$1001,$A13,Scores!$C$2:$C$1001,D$1)),"")) | E13: =IF(OR($A13="",E$1=""),"",IFERROR(AVERAGEIFS(Scores!$G$2:$G$1001,Scores!$B$2:$B$1001,$A13,Scores!$C$2:$C$1001,E$1,Scores!$A$2:$A$1001,MAXIFS(Scores!$A$2:$A$1001,Scores!$B$2:$B$1001,$A13,Scores!$C$2:$C$1001,E$1)),"")) | F13: =IF(OR($A13="",F$1=""),"",IFERROR(AVERAGEIFS(Scores!$G$2:$G$1001,Scores!$B$2:$B$1001,$A13,Scores!$C$2:$C$1001,F$1,Scores!$A$2:$A$1001,MAXIFS(Scores!$A$2:$A$1001,Scores!$B$2:$B$1001,$A13,Scores!$C$2:$C$1001,F$1)),"")) | G13: =IF(OR($A13="",G$1=""),"",IFERROR(AVERAGEIFS(Scores!$G$2:$G$1001,Scores!$B$2:$B$1001,$A13,Scores!$C$2:$C$1001,G$1,Scores!$A$2:$A$1001,MAXIFS(Scores!$A$2:$A$1001,Scores!$B$2:$B$1001,$A13,Scores!$C$2:$C$1001,G$1)),"")) | H13: =IF(OR($A13="",H$1=""),"",IFERROR(AVERAGEIFS(Scores!$G$2:$G$1001,Scores!$B$2:$B$1001,$A13,Scores!$C$2:$C$1001,H$1,Scores!$A$2:$A$1001,MAXIFS(Scores!$A$2:$A$1001,Scores!$B$2:$B$1001,$A13,Scores!$C$2:$C$1001,H$1)),"")) | I13: =IF(OR($A13="",I$1=""),"",IFERROR(AVERAGEIFS(Scores!$G$2:$G$1001,Scores!$B$2:$B$1001,$A13,Scores!$C$2:$C$1001,I$1,Scores!$A$2:$A$1001,MAXIFS(Scores!$A$2:$A$1001,Scores!$B$2:$B$1001,$A13,Scores!$C$2:$C$1001,I$1)),"")) | ... AE13: =IF(OR($A13="",AE$1=""),"",IFERROR(AVERAGEIFS(Scores!$G$2:$G$1001,Scores!$B$2:$B$1001,$A13,Scores!$C$2:$C$1001,AE$1,Scores!$A$2:$A$1001,MAXIFS(Scores!$A$2:$A$1001,Scores!$B$2:$B$1001,$A13,Scores!$C$2:$C$1001,AE$1)),"")) | AF13: =IF($A13="","",IFERROR(AVERAGE(B13:AE13),""))
... A21: =IFERROR(Config!A21,"") | B21: =IF(OR($A21="",B$1=""),"",IFERROR(AVERAGEIFS(Scores!$G$2:$G$1001,Scores!$B$2:$B$1001,$A21,Scores!$C$2:$C$1001,B$1,Scores!$A$2:$A$1001,MAXIFS(Scores!$A$2:$A$1001,Scores!$B$2:$B$1001,$A21,Scores!$C$2:$C$1001,B$1)),"")) | C21: =IF(OR($A21="",C$1=""),"",IFERROR(AVERAGEIFS(Scores!$G$2:$G$1001,Scores!$B$2:$B$1001,$A21,Scores!$C$2:$C$1001,C$1,Scores!$A$2:$A$1001,MAXIFS(Scores!$A$2:$A$1001,Scores!$B$2:$B$1001,$A21,Scores!$C$2:$C$1001,C$1)),"")) | D21: =IF(OR($A21="",D$1=""),"",IFERROR(AVERAGEIFS(Scores!$G$2:$G$1001,Scores!$B$2:$B$1001,$A21,Scores!$C$2:$C$1001,D$1,Scores!$A$2:$A$1001,MAXIFS(Scores!$A$2:$A$1001,Scores!$B$2:$B$1001,$A21,Scores!$C$2:$C$1001,D$1)),"")) | E21: =IF(OR($A21="",E$1=""),"",IFERROR(AVERAGEIFS(Scores!$G$2:$G$1001,Scores!$B$2:$B$1001,$A21,Scores!$C$2:$C$1001,E$1,Scores!$A$2:$A$1001,MAXIFS(Scores!$A$2:$A$1001,Scores!$B$2:$B$1001,$A21,Scores!$C$2:$C$1001,E$1)),"")) | F21: =IF(OR($A21="",F$1=""),"",IFERROR(AVERAGEIFS(Scores!$G$2:$G$1001,Scores!$B$2:$B$1001,$A21,Scores!$C$2:$C$1001,F$1,Scores!$A$2:$A$1001,MAXIFS(Scores!$A$2:$A$1001,Scores!$B$2:$B$1001,$A21,Scores!$C$2:$C$1001,F$1)),"")) | G21: =IF(OR($A21="",G$1=""),"",IFERROR(AVERAGEIFS(Scores!$G$2:$G$1001,Scores!$B$2:$B$1001,$A21,Scores!$C$2:$C$1001,G$1,Scores!$A$2:$A$1001,MAXIFS(Scores!$A$2:$A$1001,Scores!$B$2:$B$1001,$A21,Scores!$C$2:$C$1001,G$1)),"")) | H21: =IF(OR($A21="",H$1=""),"",IFERROR(AVERAGEIFS(Scores!$G$2:$G$1001,Scores!$B$2:$B$1001,$A21,Scores!$C$2:$C$1001,H$1,Scores!$A$2:$A$1001,MAXIFS(Scores!$A$2:$A$1001,Scores!$B$2:$B$1001,$A21,Scores!$C$2:$C$1001,H$1)),"")) | I21: =IF(OR($A21="",I$1=""),"",IFERROR(AVERAGEIFS(Scores!$G$2:$G$1001,Scores!$B$2:$B$1001,$A21,Scores!$C$2:$C$1001,I$1,Scores!$A$2:$A$1001,MAXIFS(Scores!$A$2:$A$1001,Scores!$B$2:$B$1001,$A21,Scores!$C$2:$C$1001,I$1)),"")) | ... AE21: =IF(OR($A21="",AE$1=""),"",IFERROR(AVERAGEIFS(Scores!$G$2:$G$1001,Scores!$B$2:$B$1001,$A21,Scores!$C$2:$C$1001,AE$1,Scores!$A$2:$A$1001,MAXIFS(Scores!$A$2:$A$1001,Scores!$B$2:$B$1001,$A21,Scores!$C$2:$C$1001,AE$1)),"")) | AF21: =IF($A21="","",IFERROR(AVERAGE(B21:AE21),""))
A22: Group Avg | B22: =IF(B$1="","",IFERROR(AVERAGE(B2:B21),"")) | C22: =IF(C$1="","",IFERROR(AVERAGE(C2:C21),"")) | D22: =IF(D$1="","",IFERROR(AVERAGE(D2:D21),"")) | E22: =IF(E$1="","",IFERROR(AVERAGE(E2:E21),"")) | F22: =IF(F$1="","",IFERROR(AVERAGE(F2:F21),"")) | G22: =IF(G$1="","",IFERROR(AVERAGE(G2:G21),"")) | H22: =IF(H$1="","",IFERROR(AVERAGE(H2:H21),"")) | I22: =IF(I$1="","",IFERROR(AVERAGE(I2:I21),"")) | ... AE22: =IF(AE$1="","",IFERROR(AVERAGE(AE2:AE21),""))

Sheet Training Priority
A1: Training Priority — drill weakest first | H1: (helper — safe to ignore)
H2: =IFERROR(Config!C2,"") | I2: =IF(H2="","",IFERROR(INDEX(Scoreboard!$B$22:$AE$22,MATCH(H2,Scoreboard!$B$1:$AE$1,0)),"")) | J2: =IF(H2="","",IFERROR(INDEX(Config!$D$2:$D$31,MATCH(H2,Config!$C$2:$C$31,0)),"")) | K2: =IF(OR(H2="",I2="",J2=""),"",I2-J2) | L2: =IF(OR(H2="",I2=""),"",IFERROR(INDEX(Scoreboard!$A$2:$A$21,MATCH(MIN(INDEX(Scoreboard!$B$2:$AE$21,0,MATCH(H2,Scoreboard!$B$1:$AE$1,0))),INDEX(Scoreboard!$B$2:$AE$21,0,MATCH(H2,Scoreboard!$B$1:$AE$1,0)),0)),""))
A3: Rank | B3: Subject | C3: Group Avg % | D3: Target % | E3: Gap to Target | F3: Weakest Member | H3: =IFERROR(Config!C3,"") | I3: =IF(H3="","",IFERROR(INDEX(Scoreboard!$B$22:$AE$22,MATCH(H3,Scoreboard!$B$1:$AE$1,0)),"")) | J3: =IF(H3="","",IFERROR(INDEX(Config!$D$2:$D$31,MATCH(H3,Config!$C$2:$C$31,0)),"")) | K3: =IF(OR(H3="",I3="",J3=""),"",I3-J3) | L3: =IF(OR(H3="",I3=""),"",IFERROR(INDEX(Scoreboard!$A$2:$A$21,MATCH(MIN(INDEX(Scoreboard!$B$2:$AE$21,0,MATCH(H3,Scoreboard!$B$1:$AE$1,0))),INDEX(Scoreboard!$B$2:$AE$21,0,MATCH(H3,Scoreboard!$B$1:$AE$1,0)),0)),""))
A4: =IF(B4="","",ROW()-3) | B4: =IFERROR(SORT(FILTER($H$2:$L$31,($H$2:$H$31<>"")*($I$2:$I$31<>"")),2,TRUE),"") | H4: =IFERROR(Config!C4,"") | I4: =IF(H4="","",IFERROR(INDEX(Scoreboard!$B$22:$AE$22,MATCH(H4,Scoreboard!$B$1:$AE$1,0)),"")) | J4: =IF(H4="","",IFERROR(INDEX(Config!$D$2:$D$31,MATCH(H4,Config!$C$2:$C$31,0)),"")) | K4: =IF(OR(H4="",I4="",J4=""),"",I4-J4) | L4: =IF(OR(H4="",I4=""),"",IFERROR(INDEX(Scoreboard!$A$2:$A$21,MATCH(MIN(INDEX(Scoreboard!$B$2:$AE$21,0,MATCH(H4,Scoreboard!$B$1:$AE$1,0))),INDEX(Scoreboard!$B$2:$AE$21,0,MATCH(H4,Scoreboard!$B$1:$AE$1,0)),0)),""))
A5: =IF(B5="","",ROW()-3) | H5: =IFERROR(Config!C5,"") | I5: =IF(H5="","",IFERROR(INDEX(Scoreboard!$B$22:$AE$22,MATCH(H5,Scoreboard!$B$1:$AE$1,0)),"")) | J5: =IF(H5="","",IFERROR(INDEX(Config!$D$2:$D$31,MATCH(H5,Config!$C$2:$C$31,0)),"")) | K5: =IF(OR(H5="",I5="",J5=""),"",I5-J5) | L5: =IF(OR(H5="",I5=""),"",IFERROR(INDEX(Scoreboard!$A$2:$A$21,MATCH(MIN(INDEX(Scoreboard!$B$2:$AE$21,0,MATCH(H5,Scoreboard!$B$1:$AE$1,0))),INDEX(Scoreboard!$B$2:$AE$21,0,MATCH(H5,Scoreboard!$B$1:$AE$1,0)),0)),""))
A6: =IF(B6="","",ROW()-3) | H6: =IFERROR(Config!C6,"") | I6: =IF(H6="","",IFERROR(INDEX(Scoreboard!$B$22:$AE$22,MATCH(H6,Scoreboard!$B$1:$AE$1,0)),"")) | J6: =IF(H6="","",IFERROR(INDEX(Config!$D$2:$D$31,MATCH(H6,Config!$C$2:$C$31,0)),"")) | K6: =IF(OR(H6="",I6="",J6=""),"",I6-J6) | L6: =IF(OR(H6="",I6=""),"",IFERROR(INDEX(Scoreboard!$A$2:$A$21,MATCH(MIN(INDEX(Scoreboard!$B$2:$AE$21,0,MATCH(H6,Scoreboard!$B$1:$AE$1,0))),INDEX(Scoreboard!$B$2:$AE$21,0,MATCH(H6,Scoreboard!$B$1:$AE$1,0)),0)),""))
A7: =IF(B7="","",ROW()-3) | H7: =IFERROR(Config!C7,"") | I7: =IF(H7="","",IFERROR(INDEX(Scoreboard!$B$22:$AE$22,MATCH(H7,Scoreboard!$B$1:$AE$1,0)),"")) | J7: =IF(H7="","",IFERROR(INDEX(Config!$D$2:$D$31,MATCH(H7,Config!$C$2:$C$31,0)),"")) | K7: =IF(OR(H7="",I7="",J7=""),"",I7-J7) | L7: =IF(OR(H7="",I7=""),"",IFERROR(INDEX(Scoreboard!$A$2:$A$21,MATCH(MIN(INDEX(Scoreboard!$B$2:$AE$21,0,MATCH(H7,Scoreboard!$B$1:$AE$1,0))),INDEX(Scoreboard!$B$2:$AE$21,0,MATCH(H7,Scoreboard!$B$1:$AE$1,0)),0)),""))
A8: =IF(B8="","",ROW()-3) | H8: =IFERROR(Config!C8,"") | I8: =IF(H8="","",IFERROR(INDEX(Scoreboard!$B$22:$AE$22,MATCH(H8,Scoreboard!$B$1:$AE$1,0)),"")) | J8: =IF(H8="","",IFERROR(INDEX(Config!$D$2:$D$31,MATCH(H8,Config!$C$2:$C$31,0)),"")) | K8: =IF(OR(H8="",I8="",J8=""),"",I8-J8) | L8: =IF(OR(H8="",I8=""),"",IFERROR(INDEX(Scoreboard!$A$2:$A$21,MATCH(MIN(INDEX(Scoreboard!$B$2:$AE$21,0,MATCH(H8,Scoreboard!$B$1:$AE$1,0))),INDEX(Scoreboard!$B$2:$AE$21,0,MATCH(H8,Scoreboard!$B$1:$AE$1,0)),0)),""))
A9: =IF(B9="","",ROW()-3) | H9: =IFERROR(Config!C9,"") | I9: =IF(H9="","",IFERROR(INDEX(Scoreboard!$B$22:$AE$22,MATCH(H9,Scoreboard!$B$1:$AE$1,0)),"")) | J9: =IF(H9="","",IFERROR(INDEX(Config!$D$2:$D$31,MATCH(H9,Config!$C$2:$C$31,0)),"")) | K9: =IF(OR(H9="",I9="",J9=""),"",I9-J9) | L9: =IF(OR(H9="",I9=""),"",IFERROR(INDEX(Scoreboard!$A$2:$A$21,MATCH(MIN(INDEX(Scoreboard!$B$2:$AE$21,0,MATCH(H9,Scoreboard!$B$1:$AE$1,0))),INDEX(Scoreboard!$B$2:$AE$21,0,MATCH(H9,Scoreboard!$B$1:$AE$1,0)),0)),""))
A10: =IF(B10="","",ROW()-3) | H10: =IFERROR(Config!C10,"") | I10: =IF(H10="","",IFERROR(INDEX(Scoreboard!$B$22:$AE$22,MATCH(H10,Scoreboard!$B$1:$AE$1,0)),"")) | J10: =IF(H10="","",IFERROR(INDEX(Config!$D$2:$D$31,MATCH(H10,Config!$C$2:$C$31,0)),"")) | K10: =IF(OR(H10="",I10="",J10=""),"",I10-J10) | L10: =IF(OR(H10="",I10=""),"",IFERROR(INDEX(Scoreboard!$A$2:$A$21,MATCH(MIN(INDEX(Scoreboard!$B$2:$AE$21,0,MATCH(H10,Scoreboard!$B$1:$AE$1,0))),INDEX(Scoreboard!$B$2:$AE$21,0,MATCH(H10,Scoreboard!$B$1:$AE$1,0)),0)),""))
A11: =IF(B11="","",ROW()-3) | H11: =IFERROR(Config!C11,"") | I11: =IF(H11="","",IFERROR(INDEX(Scoreboard!$B$22:$AE$22,MATCH(H11,Scoreboard!$B$1:$AE$1,0)),"")) | J11: =IF(H11="","",IFERROR(INDEX(Config!$D$2:$D$31,MATCH(H11,Config!$C$2:$C$31,0)),"")) | K11: =IF(OR(H11="",I11="",J11=""),"",I11-J11) | L11: =IF(OR(H11="",I11=""),"",IFERROR(INDEX(Scoreboard!$A$2:$A$21,MATCH(MIN(INDEX(Scoreboard!$B$2:$AE$21,0,MATCH(H11,Scoreboard!$B$1:$AE$1,0))),INDEX(Scoreboard!$B$2:$AE$21,0,MATCH(H11,Scoreboard!$B$1:$AE$1,0)),0)),""))
A12: =IF(B12="","",ROW()-3) | H12: =IFERROR(Config!C12,"") | I12: =IF(H12="","",IFERROR(INDEX(Scoreboard!$B$22:$AE$22,MATCH(H12,Scoreboard!$B$1:$AE$1,0)),"")) | J12: =IF(H12="","",IFERROR(INDEX(Config!$D$2:$D$31,MATCH(H12,Config!$C$2:$C$31,0)),"")) | K12: =IF(OR(H12="",I12="",J12=""),"",I12-J12) | L12: =IF(OR(H12="",I12=""),"",IFERROR(INDEX(Scoreboard!$A$2:$A$21,MATCH(MIN(INDEX(Scoreboard!$B$2:$AE$21,0,MATCH(H12,Scoreboard!$B$1:$AE$1,0))),INDEX(Scoreboard!$B$2:$AE$21,0,MATCH(H12,Scoreboard!$B$1:$AE$1,0)),0)),""))
A13: =IF(B13="","",ROW()-3) | H13: =IFERROR(Config!C13,"") | I13: =IF(H13="","",IFERROR(INDEX(Scoreboard!$B$22:$AE$22,MATCH(H13,Scoreboard!$B$1:$AE$1,0)),"")) | J13: =IF(H13="","",IFERROR(INDEX(Config!$D$2:$D$31,MATCH(H13,Config!$C$2:$C$31,0)),"")) | K13: =IF(OR(H13="",I13="",J13=""),"",I13-J13) | L13: =IF(OR(H13="",I13=""),"",IFERROR(INDEX(Scoreboard!$A$2:$A$21,MATCH(MIN(INDEX(Scoreboard!$B$2:$AE$21,0,MATCH(H13,Scoreboard!$B$1:$AE$1,0))),INDEX(Scoreboard!$B$2:$AE$21,0,MATCH(H13,Scoreboard!$B$1:$AE$1,0)),0)),""))
A14: =IF(B14="","",ROW()-3) | H14: =IFERROR(Config!C14,"") | I14: =IF(H14="","",IFERROR(INDEX(Scoreboard!$B$22:$AE$22,MATCH(H14,Scoreboard!$B$1:$AE$1,0)),"")) | J14: =IF(H14="","",IFERROR(INDEX(Config!$D$2:$D$31,MATCH(H14,Config!$C$2:$C$31,0)),"")) | K14: =IF(OR(H14="",I14="",J14=""),"",I14-J14) | L14: =IF(OR(H14="",I14=""),"",IFERROR(INDEX(Scoreboard!$A$2:$A$21,MATCH(MIN(INDEX(Scoreboard!$B$2:$AE$21,0,MATCH(H14,Scoreboard!$B$1:$AE$1,0))),INDEX(Scoreboard!$B$2:$AE$21,0,MATCH(H14,Scoreboard!$B$1:$AE$1,0)),0)),""))
A15: =IF(B15="","",ROW()-3) | H15: =IFERROR(Config!C15,"") | I15: =IF(H15="","",IFERROR(INDEX(Scoreboard!$B$22:$AE$22,MATCH(H15,Scoreboard!$B$1:$AE$1,0)),"")) | J15: =IF(H15="","",IFERROR(INDEX(Config!$D$2:$D$31,MATCH(H15,Config!$C$2:$C$31,0)),"")) | K15: =IF(OR(H15="",I15="",J15=""),"",I15-J15) | L15: =IF(OR(H15="",I15=""),"",IFERROR(INDEX(Scoreboard!$A$2:$A$21,MATCH(MIN(INDEX(Scoreboard!$B$2:$AE$21,0,MATCH(H15,Scoreboard!$B$1:$AE$1,0))),INDEX(Scoreboard!$B$2:$AE$21,0,MATCH(H15,Scoreboard!$B$1:$AE$1,0)),0)),""))
A16: =IF(B16="","",ROW()-3) | H16: =IFERROR(Config!C16,"") | I16: =IF(H16="","",IFERROR(INDEX(Scoreboard!$B$22:$AE$22,MATCH(H16,Scoreboard!$B$1:$AE$1,0)),"")) | J16: =IF(H16="","",IFERROR(INDEX(Config!$D$2:$D$31,MATCH(H16,Config!$C$2:$C$31,0)),"")) | K16: =IF(OR(H16="",I16="",J16=""),"",I16-J16) | L16: =IF(OR(H16="",I16=""),"",IFERROR(INDEX(Scoreboard!$A$2:$A$21,MATCH(MIN(INDEX(Scoreboard!$B$2:$AE$21,0,MATCH(H16,Scoreboard!$B$1:$AE$1,0))),INDEX(Scoreboard!$B$2:$AE$21,0,MATCH(H16,Scoreboard!$B$1:$AE$1,0)),0)),""))
... A31: =IF(B31="","",ROW()-3) | H31: =IFERROR(Config!C31,"") | I31: =IF(H31="","",IFERROR(INDEX(Scoreboard!$B$22:$AE$22,MATCH(H31,Scoreboard!$B$1:$AE$1,0)),"")) | J31: =IF(H31="","",IFERROR(INDEX(Config!$D$2:$D$31,MATCH(H31,Config!$C$2:$C$31,0)),"")) | K31: =IF(OR(H31="",I31="",J31=""),"",I31-J31) | L31: =IF(OR(H31="",I31=""),"",IFERROR(INDEX(Scoreboard!$A$2:$A$21,MATCH(MIN(INDEX(Scoreboard!$B$2:$AE$21,0,MATCH(H31,Scoreboard!$B$1:$AE$1,0))),INDEX(Scoreboard!$B$2:$AE$21,0,MATCH(H31,Scoreboard!$B$1:$AE$1,0)),0)),""))
A32: =IF(B32="","",ROW()-3)
A33: =IF(B33="","",ROW()-3)

Sheet Daily Schedule
A1: =IF(C1="","Add scores to see today's drill","Today (" & TEXT(Config!$I$4,"ddd dd mmm yyyy") & ") — drill:") | C1: =IFERROR('Training Priority'!$B$4,IFERROR(Config!$C$2,""))
A3: Date | B3: Subject (weakest first) | C3: Group Avg % now | D3: Manual override
A4: =Config!$I$4 | B4: =IF($D4<>"",$D4,IFERROR(INDEX('Training Priority'!$B$4:$B$33,1),IFERROR(INDEX(Config!$C$2:$C$31,1),""))) | C4: =IF($B4="","",IFERROR(INDEX(Scoreboard!$B$22:$AE$22,MATCH($B4,Scoreboard!$B$1:$AE$1,0)),""))
A5: =A4+1 | B5: =IF($D5<>"",$D5,IFERROR(INDEX('Training Priority'!$B$4:$B$33,2),IFERROR(INDEX(Config!$C$2:$C$31,2),""))) | C5: =IF($B5="","",IFERROR(INDEX(Scoreboard!$B$22:$AE$22,MATCH($B5,Scoreboard!$B$1:$AE$1,0)),""))
A6: =A5+1 | B6: =IF($D6<>"",$D6,IFERROR(INDEX('Training Priority'!$B$4:$B$33,3),IFERROR(INDEX(Config!$C$2:$C$31,3),""))) | C6: =IF($B6="","",IFERROR(INDEX(Scoreboard!$B$22:$AE$22,MATCH($B6,Scoreboard!$B$1:$AE$1,0)),""))
A7: =A6+1 | B7: =IF($D7<>"",$D7,IFERROR(INDEX('Training Priority'!$B$4:$B$33,4),IFERROR(INDEX(Config!$C$2:$C$31,4),""))) | C7: =IF($B7="","",IFERROR(INDEX(Scoreboard!$B$22:$AE$22,MATCH($B7,Scoreboard!$B$1:$AE$1,0)),""))
A8: =A7+1 | B8: =IF($D8<>"",$D8,IFERROR(INDEX('Training Priority'!$B$4:$B$33,5),IFERROR(INDEX(Config!$C$2:$C$31,5),""))) | C8: =IF($B8="","",IFERROR(INDEX(Scoreboard!$B$22:$AE$22,MATCH($B8,Scoreboard!$B$1:$AE$1,0)),""))
A9: =A8+1 | B9: =IF($D9<>"",$D9,IFERROR(INDEX('Training Priority'!$B$4:$B$33,6),IFERROR(INDEX(Config!$C$2:$C$31,6),""))) | C9: =IF($B9="","",IFERROR(INDEX(Scoreboard!$B$22:$AE$22,MATCH($B9,Scoreboard!$B$1:$AE$1,0)),""))
A10: =A9+1 | B10: =IF($D10<>"",$D10,IFERROR(INDEX('Training Priority'!$B$4:$B$33,7),IFERROR(INDEX(Config!$C$2:$C$31,7),""))) | C10: =IF($B10="","",IFERROR(INDEX(Scoreboard!$B$22:$AE$22,MATCH($B10,Scoreboard!$B$1:$AE$1,0)),""))
A12: Type a subject in 'Manual override' to pin a day.

Sheet Gap Analysis
A1: Gap vs Group Avg (green = ahead, red = behind)
A3: Member \ Subject | B3: =IFERROR(Config!C2,"") | C3: =IFERROR(Config!C3,"") | D3: =IFERROR(Config!C4,"") | E3: =IFERROR(Config!C5,"") | F3: =IFERROR(Config!C6,"") | G3: =IFERROR(Config!C7,"") | H3: =IFERROR(Config!C8,"") | I3: =IFERROR(Config!C9,"") | J3: =IFERROR(Config!C10,"") | K3: =IFERROR(Config!C11,"") | L3: =IFERROR(Config!C12,"") | M3: =IFERROR(Config!C13,"") | N3: =IFERROR(Config!C14,"") | O3: =IFERROR(Config!C15,"") | P3: =IFERROR(Config!C16,"") | Q3: =IFERROR(Config!C17,"") | R3: =IFERROR(Config!C18,"") | S3: =IFERROR(Config!C19,"") | T3: =IFERROR(Config!C20,"") | U3: =IFERROR(Config!C21,"") | V3: =IFERROR(Config!C22,"") | W3: =IFERROR(Config!C23,"") | X3: =IFERROR(Config!C24,"") | Y3: =IFERROR(Config!C25,"") | Z3: =IFERROR(Config!C26,"") | AA3: =IFERROR(Config!C27,"") | AB3: =IFERROR(Config!C28,"") | AC3: =IFERROR(Config!C29,"") | AD3: =IFERROR(Config!C30,"") | AE3: =IFERROR(Config!C31,"")
A4: =IFERROR(Config!A2,"") | B4: =IF(OR($A4="",B$3=""),"",IFERROR(INDEX(Scoreboard!$B$2:$AE$21,MATCH($A4,Scoreboard!$A$2:$A$21,0),MATCH(B$3,Scoreboard!$B$1:$AE$1,0))-INDEX(Scoreboard!$B$22:$AE$22,MATCH(B$3,Scoreboard!$B$1:$AE$1,0)),"")) | C4: =IF(OR($A4="",C$3=""),"",IFERROR(INDEX(Scoreboard!$B$2:$AE$21,MATCH($A4,Scoreboard!$A$2:$A$21,0),MATCH(C$3,Scoreboard!$B$1:$AE$1,0))-INDEX(Scoreboard!$B$22:$AE$22,MATCH(C$3,Scoreboard!$B$1:$AE$1,0)),"")) | D4: =IF(OR($A4="",D$3=""),"",IFERROR(INDEX(Scoreboard!$B$2:$AE$21,MATCH($A4,Scoreboard!$A$2:$A$21,0),MATCH(D$3,Scoreboard!$B$1:$AE$1,0))-INDEX(Scoreboard!$B$22:$AE$22,MATCH(D$3,Scoreboard!$B$1:$AE$1,0)),"")) | E4: =IF(OR($A4="",E$3=""),"",IFERROR(INDEX(Scoreboard!$B$2:$AE$21,MATCH($A4,Scoreboard!$A$2:$A$21,0),MATCH(E$3,Scoreboard!$B$1:$AE$1,0))-INDEX(Scoreboard!$B$22:$AE$22,MATCH(E$3,Scoreboard!$B$1:$AE$1,0)),"")) | F4: =IF(OR($A4="",F$3=""),"",IFERROR(INDEX(Scoreboard!$B$2:$AE$21,MATCH($A4,Scoreboard!$A$2:$A$21,0),MATCH(F$3,Scoreboard!$B$1:$AE$1,0))-INDEX(Scoreboard!$B$22:$AE$22,MATCH(F$3,Scoreboard!$B$1:$AE$1,0)),"")) | G4: =IF(OR($A4="",G$3=""),"",IFERROR(INDEX(Scoreboard!$B$2:$AE$21,MATCH($A4,Scoreboard!$A$2:$A$21,0),MATCH(G$3,Scoreboard!$B$1:$AE$1,0))-INDEX(Scoreboard!$B$22:$AE$22,MATCH(G$3,Scoreboard!$B$1:$AE$1,0)),"")) | H4: =IF(OR($A4="",H$3=""),"",IFERROR(INDEX(Scoreboard!$B$2:$AE$21,MATCH($A4,Scoreboard!$A$2:$A$21,0),MATCH(H$3,Scoreboard!$B$1:$AE$1,0))-INDEX(Scoreboard!$B$22:$AE$22,MATCH(H$3,Scoreboard!$B$1:$AE$1,0)),"")) | I4: =IF(OR($A4="",I$3=""),"",IFERROR(INDEX(Scoreboard!$B$2:$AE$21,MATCH($A4,Scoreboard!$A$2:$A$21,0),MATCH(I$3,Scoreboard!$B$1:$AE$1,0))-INDEX(Scoreboard!$B$22:$AE$22,MATCH(I$3,Scoreboard!$B$1:$AE$1,0)),"")) | ... AE4: =IF(OR($A4="",AE$3=""),"",IFERROR(INDEX(Scoreboard!$B$2:$AE$21,MATCH($A4,Scoreboard!$A$2:$A$21,0),MATCH(AE$3,Scoreboard!$B$1:$AE$1,0))-INDEX(Scoreboard!$B$22:$AE$22,MATCH(AE$3,Scoreboard!$B$1:$AE$1,0)),""))
A5: =IFERROR(Config!A3,"") | B5: =IF(OR($A5="",B$3=""),"",IFERROR(INDEX(Scoreboard!$B$2:$AE$21,MATCH($A5,Scoreboard!$A$2:$A$21,0),MATCH(B$3,Scoreboard!$B$1:$AE$1,0))-INDEX(Scoreboard!$B$22:$AE$22,MATCH(B$3,Scoreboard!$B$1:$AE$1,0)),"")) | C5: =IF(OR($A5="",C$3=""),"",IFERROR(INDEX(Scoreboard!$B$2:$AE$21,MATCH($A5,Scoreboard!$A$2:$A$21,0),MATCH(C$3,Scoreboard!$B$1:$AE$1,0))-INDEX(Scoreboard!$B$22:$AE$22,MATCH(C$3,Scoreboard!$B$1:$AE$1,0)),"")) | D5: =IF(OR($A5="",D$3=""),"",IFERROR(INDEX(Scoreboard!$B$2:$AE$21,MATCH($A5,Scoreboard!$A$2:$A$21,0),MATCH(D$3,Scoreboard!$B$1:$AE$1,0))-INDEX(Scoreboard!$B$22:$AE$22,MATCH(D$3,Scoreboard!$B$1:$AE$1,0)),"")) | E5: =IF(OR($A5="",E$3=""),"",IFERROR(INDEX(Scoreboard!$B$2:$AE$21,MATCH($A5,Scoreboard!$A$2:$A$21,0),MATCH(E$3,Scoreboard!$B$1:$AE$1,0))-INDEX(Scoreboard!$B$22:$AE$22,MATCH(E$3,Scoreboard!$B$1:$AE$1,0)),"")) | F5: =IF(OR($A5="",F$3=""),"",IFERROR(INDEX(Scoreboard!$B$2:$AE$21,MATCH($A5,Scoreboard!$A$2:$A$21,0),MATCH(F$3,Scoreboard!$B$1:$AE$1,0))-INDEX(Scoreboard!$B$22:$AE$22,MATCH(F$3,Scoreboard!$B$1:$AE$1,0)),"")) | G5: =IF(OR($A5="",G$3=""),"",IFERROR(INDEX(Scoreboard!$B$2:$AE$21,MATCH($A5,Scoreboard!$A$2:$A$21,0),MATCH(G$3,Scoreboard!$B$1:$AE$1,0))-INDEX(Scoreboard!$B$22:$AE$22,MATCH(G$3,Scoreboard!$B$1:$AE$1,0)),"")) | H5: =IF(OR($A5="",H$3=""),"",IFERROR(INDEX(Scoreboard!$B$2:$AE$21,MATCH($A5,Scoreboard!$A$2:$A$21,0),MATCH(H$3,Scoreboard!$B$1:$AE$1,0))-INDEX(Scoreboard!$B$22:$AE$22,MATCH(H$3,Scoreboard!$B$1:$AE$1,0)),"")) | I5: =IF(OR($A5="",I$3=""),"",IFERROR(INDEX(Scoreboard!$B$2:$AE$21,MATCH($A5,Scoreboard!$A$2:$A$21,0),MATCH(I$3,Scoreboard!$B$1:$AE$1,0))-INDEX(Scoreboard!$B$22:$AE$22,MATCH(I$3,Scoreboard!$B$1:$AE$1,0)),"")) | ... AE5: =IF(OR($A5="",AE$3=""),"",IFERROR(INDEX(Scoreboard!$B$2:$AE$21,MATCH($A5,Scoreboard!$A$2:$A$21,0),MATCH(AE$3,Scoreboard!$B$1:$AE$1,0))-INDEX(Scoreboard!$B$22:$AE$22,MATCH(AE$3,Scoreboard!$B$1:$AE$1,0)),""))
A6: =IFERROR(Config!A4,"") | B6: =IF(OR($A6="",B$3=""),"",IFERROR(INDEX(Scoreboard!$B$2:$AE$21,MATCH($A6,Scoreboard!$A$2:$A$21,0),MATCH(B$3,Scoreboard!$B$1:$AE$1,0))-INDEX(Scoreboard!$B$22:$AE$22,MATCH(B$3,Scoreboard!$B$1:$AE$1,0)),"")) | C6: =IF(OR($A6="",C$3=""),"",IFERROR(INDEX(Scoreboard!$B$2:$AE$21,MATCH($A6,Scoreboard!$A$2:$A$21,0),MATCH(C$3,Scoreboard!$B$1:$AE$1,0))-INDEX(Scoreboard!$B$22:$AE$22,MATCH(C$3,Scoreboard!$B$1:$AE$1,0)),"")) | D6: =IF(OR($A6="",D$3=""),"",IFERROR(INDEX(Scoreboard!$B$2:$AE$21,MATCH($A6,Scoreboard!$A$2:$A$21,0),MATCH(D$3,Scoreboard!$B$1:$AE$1,0))-INDEX(Scoreboard!$B$22:$AE$22,MATCH(D$3,Scoreboard!$B$1:$AE$1,0)),"")) | E6: =IF(OR($A6="",E$3=""),"",IFERROR(INDEX(Scoreboard!$B$2:$AE$21,MATCH($A6,Scoreboard!$A$2:$A$21,0),MATCH(E$3,Scoreboard!$B$1:$AE$1,0))-INDEX(Scoreboard!$B$22:$AE$22,MATCH(E$3,Scoreboard!$B$1:$AE$1,0)),"")) | F6: =IF(OR($A6="",F$3=""),"",IFERROR(INDEX(Scoreboard!$B$2:$AE$21,MATCH($A6,Scoreboard!$A$2:$A$21,0),MATCH(F$3,Scoreboard!$B$1:$AE$1,0))-INDEX(Scoreboard!$B$22:$AE$22,MATCH(F$3,Scoreboard!$B$1:$AE$1,0)),"")) | G6: =IF(OR($A6="",G$3=""),"",IFERROR(INDEX(Scoreboard!$B$2:$AE$21,MATCH($A6,Scoreboard!$A$2:$A$21,0),MATCH(G$3,Scoreboard!$B$1:$AE$1,0))-INDEX(Scoreboard!$B$22:$AE$22,MATCH(G$3,Scoreboard!$B$1:$AE$1,0)),"")) | H6: =IF(OR($A6="",H$3=""),"",IFERROR(INDEX(Scoreboard!$B$2:$AE$21,MATCH($A6,Scoreboard!$A$2:$A$21,0),MATCH(H$3,Scoreboard!$B$1:$AE$1,0))-INDEX(Scoreboard!$B$22:$AE$22,MATCH(H$3,Scoreboard!$B$1:$AE$1,0)),"")) | I6: =IF(OR($A6="",I$3=""),"",IFERROR(INDEX(Scoreboard!$B$2:$AE$21,MATCH($A6,Scoreboard!$A$2:$A$21,0),MATCH(I$3,Scoreboard!$B$1:$AE$1,0))-INDEX(Scoreboard!$B$22:$AE$22,MATCH(I$3,Scoreboard!$B$1:$AE$1,0)),"")) | ... AE6: =IF(OR($A6="",AE$3=""),"",IFERROR(INDEX(Scoreboard!$B$2:$AE$21,MATCH($A6,Scoreboard!$A$2:$A$21,0),MATCH(AE$3,Scoreboard!$B$1:$AE$1,0))-INDEX(Scoreboard!$B$22:$AE$22,MATCH(AE$3,Scoreboard!$B$1:$AE$1,0)),""))
A7: =IFERROR(Config!A5,"") | B7: =IF(OR($A7="",B$3=""),"",IFERROR(INDEX(Scoreboard!$B$2:$AE$21,MATCH($A7,Scoreboard!$A$2:$A$21,0),MATCH(B$3,Scoreboard!$B$1:$AE$1,0))-INDEX(Scoreboard!$B$22:$AE$22,MATCH(B$3,Scoreboard!$B$1:$AE$1,0)),"")) | C7: =IF(OR($A7="",C$3=""),"",IFERROR(INDEX(Scoreboard!$B$2:$AE$21,MATCH($A7,Scoreboard!$A$2:$A$21,0),MATCH(C$3,Scoreboard!$B$1:$AE$1,0))-INDEX(Scoreboard!$B$22:$AE$22,MATCH(C$3,Scoreboard!$B$1:$AE$1,0)),"")) | D7: =IF(OR($A7="",D$3=""),"",IFERROR(INDEX(Scoreboard!$B$2:$AE$21,MATCH($A7,Scoreboard!$A$2:$A$21,0),MATCH(D$3,Scoreboard!$B$1:$AE$1,0))-INDEX(Scoreboard!$B$22:$AE$22,MATCH(D$3,Scoreboard!$B$1:$AE$1,0)),"")) | E7: =IF(OR($A7="",E$3=""),"",IFERROR(INDEX(Scoreboard!$B$2:$AE$21,MATCH($A7,Scoreboard!$A$2:$A$21,0),MATCH(E$3,Scoreboard!$B$1:$AE$1,0))-INDEX(Scoreboard!$B$22:$AE$22,MATCH(E$3,Scoreboard!$B$1:$AE$1,0)),"")) | F7: =IF(OR($A7="",F$3=""),"",IFERROR(INDEX(Scoreboard!$B$2:$AE$21,MATCH($A7,Scoreboard!$A$2:$A$21,0),MATCH(F$3,Scoreboard!$B$1:$AE$1,0))-INDEX(Scoreboard!$B$22:$AE$22,MATCH(F$3,Scoreboard!$B$1:$AE$1,0)),"")) | G7: =IF(OR($A7="",G$3=""),"",IFERROR(INDEX(Scoreboard!$B$2:$AE$21,MATCH($A7,Scoreboard!$A$2:$A$21,0),MATCH(G$3,Scoreboard!$B$1:$AE$1,0))-INDEX(Scoreboard!$B$22:$AE$22,MATCH(G$3,Scoreboard!$B$1:$AE$1,0)),"")) | H7: =IF(OR($A7="",H$3=""),"",IFERROR(INDEX(Scoreboard!$B$2:$AE$21,MATCH($A7,Scoreboard!$A$2:$A$21,0),MATCH(H$3,Scoreboard!$B$1:$AE$1,0))-INDEX(Scoreboard!$B$22:$AE$22,MATCH(H$3,Scoreboard!$B$1:$AE$1,0)),"")) | I7: =IF(OR($A7="",I$3=""),"",IFERROR(INDEX(Scoreboard!$B$2:$AE$21,MATCH($A7,Scoreboard!$A$2:$A$21,0),MATCH(I$3,Scoreboard!$B$1:$AE$1,0))-INDEX(Scoreboard!$B$22:$AE$22,MATCH(I$3,Scoreboard!$B$1:$AE$1,0)),"")) | ... AE7: =IF(OR($A7="",AE$3=""),"",IFERROR(INDEX(Scoreboard!$B$2:$AE$21,MATCH($A7,Scoreboard!$A$2:$A$21,0),MATCH(AE$3,Scoreboard!$B$1:$AE$1,0))-INDEX(Scoreboard!$B$22:$AE$22,MATCH(AE$3,Scoreboard!$B$1:$AE$1,0)),""))
A8: =IFERROR(Config!A6,"") | B8: =IF(OR($A8="",B$3=""),"",IFERROR(INDEX(Scoreboard!$B$2:$AE$21,MATCH($A8,Scoreboard!$A$2:$A$21,0),MATCH(B$3,Scoreboard!$B$1:$AE$1,0))-INDEX(Scoreboard!$B$22:$AE$22,MATCH(B$3,Scoreboard!$B$1:$AE$1,0)),"")) | C8: =IF(OR($A8="",C$3=""),"",IFERROR(INDEX(Scoreboard!$B$2:$AE$21,MATCH($A8,Scoreboard!$A$2:$A$21,0),MATCH(C$3,Scoreboard!$B$1:$AE$1,0))-INDEX(Scoreboard!$B$22:$AE$22,MATCH(C$3,Scoreboard!$B$1:$AE$1,0)),"")) | D8: =IF(OR($A8="",D$3=""),"",IFERROR(INDEX(Scoreboard!$B$2:$AE$21,MATCH($A8,Scoreboard!$A$2:$A$21,0),MATCH(D$3,Scoreboard!$B$1:$AE$1,0))-INDEX(Scoreboard!$B$22:$AE$22,MATCH(D$3,Scoreboard!$B$1:$AE$1,0)),"")) | E8: =IF(OR($A8="",E$3=""),"",IFERROR(INDEX(Scoreboard!$B$2:$AE$21,MATCH($A8,Scoreboard!$A$2:$A$21,0),MATCH(E$3,Scoreboard!$B$1:$AE$1,0))-INDEX(Scoreboard!$B$22:$AE$22,MATCH(E$3,Scoreboard!$B$1:$AE$1,0)),"")) | F8: =IF(OR($A8="",F$3=""),"",IFERROR(INDEX(Scoreboard!$B$2:$AE$21,MATCH($A8,Scoreboard!$A$2:$A$21,0),MATCH(F$3,Scoreboard!$B$1:$AE$1,0))-INDEX(Scoreboard!$B$22:$AE$22,MATCH(F$3,Scoreboard!$B$1:$AE$1,0)),"")) | G8: =IF(OR($A8="",G$3=""),"",IFERROR(INDEX(Scoreboard!$B$2:$AE$21,MATCH($A8,Scoreboard!$A$2:$A$21,0),MATCH(G$3,Scoreboard!$B$1:$AE$1,0))-INDEX(Scoreboard!$B$22:$AE$22,MATCH(G$3,Scoreboard!$B$1:$AE$1,0)),"")) | H8: =IF(OR($A8="",H$3=""),"",IFERROR(INDEX(Scoreboard!$B$2:$AE$21,MATCH($A8,Scoreboard!$A$2:$A$21,0),MATCH(H$3,Scoreboard!$B$1:$AE$1,0))-INDEX(Scoreboard!$B$22:$AE$22,MATCH(H$3,Scoreboard!$B$1:$AE$1,0)),"")) | I8: =IF(OR($A8="",I$3=""),"",IFERROR(INDEX(Scoreboard!$B$2:$AE$21,MATCH($A8,Scoreboard!$A$2:$A$21,0),MATCH(I$3,Scoreboard!$B$1:$AE$1,0))-INDEX(Scoreboard!$B$22:$AE$22,MATCH(I$3,Scoreboard!$B$1:$AE$1,0)),"")) | ... AE8: =IF(OR($A8="",AE$3=""),"",IFERROR(INDEX(Scoreboard!$B$2:$AE$21,MATCH($A8,Scoreboard!$A$2:$A$21,0),MATCH(AE$3,Scoreboard!$B$1:$AE$1,0))-INDEX(Scoreboard!$B$22:$AE$22,MATCH(AE$3,Scoreboard!$B$1:$AE$1,0)),""))
A9: =IFERROR(Config!A7,"") | B9: =IF(OR($A9="",B$3=""),"",IFERROR(INDEX(Scoreboard!$B$2:$AE$21,MATCH($A9,Scoreboard!$A$2:$A$21,0),MATCH(B$3,Scoreboard!$B$1:$AE$1,0))-INDEX(Scoreboard!$B$22:$AE$22,MATCH(B$3,Scoreboard!$B$1:$AE$1,0)),"")) | C9: =IF(OR($A9="",C$3=""),"",IFERROR(INDEX(Scoreboard!$B$2:$AE$21,MATCH($A9,Scoreboard!$A$2:$A$21,0),MATCH(C$3,Scoreboard!$B$1:$AE$1,0))-INDEX(Scoreboard!$B$22:$AE$22,MATCH(C$3,Scoreboard!$B$1:$AE$1,0)),"")) | D9: =IF(OR($A9="",D$3=""),"",IFERROR(INDEX(Scoreboard!$B$2:$AE$21,MATCH($A9,Scoreboard!$A$2:$A$21,0),MATCH(D$3,Scoreboard!$B$1:$AE$1,0))-INDEX(Scoreboard!$B$22:$AE$22,MATCH(D$3,Scoreboard!$B$1:$AE$1,0)),"")) | E9: =IF(OR($A9="",E$3=""),"",IFERROR(INDEX(Scoreboard!$B$2:$AE$21,MATCH($A9,Scoreboard!$A$2:$A$21,0),MATCH(E$3,Scoreboard!$B$1:$AE$1,0))-INDEX(Scoreboard!$B$22:$AE$22,MATCH(E$3,Scoreboard!$B$1:$AE$1,0)),"")) | F9: =IF(OR($A9="",F$3=""),"",IFERROR(INDEX(Scoreboard!$B$2:$AE$21,MATCH($A9,Scoreboard!$A$2:$A$21,0),MATCH(F$3,Scoreboard!$B$1:$AE$1,0))-INDEX(Scoreboard!$B$22:$AE$22,MATCH(F$3,Scoreboard!$B$1:$AE$1,0)),"")) | G9: =IF(OR($A9="",G$3=""),"",IFERROR(INDEX(Scoreboard!$B$2:$AE$21,MATCH($A9,Scoreboard!$A$2:$A$21,0),MATCH(G$3,Scoreboard!$B$1:$AE$1,0))-INDEX(Scoreboard!$B$22:$AE$22,MATCH(G$3,Scoreboard!$B$1:$AE$1,0)),"")) | H9: =IF(OR($A9="",H$3=""),"",IFERROR(INDEX(Scoreboard!$B$2:$AE$21,MATCH($A9,Scoreboard!$A$2:$A$21,0),MATCH(H$3,Scoreboard!$B$1:$AE$1,0))-INDEX(Scoreboard!$B$22:$AE$22,MATCH(H$3,Scoreboard!$B$1:$AE$1,0)),"")) | I9: =IF(OR($A9="",I$3=""),"",IFERROR(INDEX(Scoreboard!$B$2:$AE$21,MATCH($A9,Scoreboard!$A$2:$A$21,0),MATCH(I$3,Scoreboard!$B$1:$AE$1,0))-INDEX(Scoreboard!$B$22:$AE$22,MATCH(I$3,Scoreboard!$B$1:$AE$1,0)),"")) | ... AE9: =IF(OR($A9="",AE$3=""),"",IFERROR(INDEX(Scoreboard!$B$2:$AE$21,MATCH($A9,Scoreboard!$A$2:$A$21,0),MATCH(AE$3,Scoreboard!$B$1:$AE$1,0))-INDEX(Scoreboard!$B$22:$AE$22,MATCH(AE$3,Scoreboard!$B$1:$AE$1,0)),""))
A10: =IFERROR(Config!A8,"") | B10: =IF(OR($A10="",B$3=""),"",IFERROR(INDEX(Scoreboard!$B$2:$AE$21,MATCH($A10,Scoreboard!$A$2:$A$21,0),MATCH(B$3,Scoreboard!$B$1:$AE$1,0))-INDEX(Scoreboard!$B$22:$AE$22,MATCH(B$3,Scoreboard!$B$1:$AE$1,0)),"")) | C10: =IF(OR($A10="",C$3=""),"",IFERROR(INDEX(Scoreboard!$B$2:$AE$21,MATCH($A10,Scoreboard!$A$2:$A$21,0),MATCH(C$3,Scoreboard!$B$1:$AE$1,0))-INDEX(Scoreboard!$B$22:$AE$22,MATCH(C$3,Scoreboard!$B$1:$AE$1,0)),"")) | D10: =IF(OR($A10="",D$3=""),"",IFERROR(INDEX(Scoreboard!$B$2:$AE$21,MATCH($A10,Scoreboard!$A$2:$A$21,0),MATCH(D$3,Scoreboard!$B$1:$AE$1,0))-INDEX(Scoreboard!$B$22:$AE$22,MATCH(D$3,Scoreboard!$B$1:$AE$1,0)),"")) | E10: =IF(OR($A10="",E$3=""),"",IFERROR(INDEX(Scoreboard!$B$2:$AE$21,MATCH($A10,Scoreboard!$A$2:$A$21,0),MATCH(E$3,Scoreboard!$B$1:$AE$1,0))-INDEX(Scoreboard!$B$22:$AE$22,MATCH(E$3,Scoreboard!$B$1:$AE$1,0)),"")) | F10: =IF(OR($A10="",F$3=""),"",IFERROR(INDEX(Scoreboard!$B$2:$AE$21,MATCH($A10,Scoreboard!$A$2:$A$21,0),MATCH(F$3,Scoreboard!$B$1:$AE$1,0))-INDEX(Scoreboard!$B$22:$AE$22,MATCH(F$3,Scoreboard!$B$1:$AE$1,0)),"")) | G10: =IF(OR($A10="",G$3=""),"",IFERROR(INDEX(Scoreboard!$B$2:$AE$21,MATCH($A10,Scoreboard!$A$2:$A$21,0),MATCH(G$3,Scoreboard!$B$1:$AE$1,0))-INDEX(Scoreboard!$B$22:$AE$22,MATCH(G$3,Scoreboard!$B$1:$AE$1,0)),"")) | H10: =IF(OR($A10="",H$3=""),"",IFERROR(INDEX(Scoreboard!$B$2:$AE$21,MATCH($A10,Scoreboard!$A$2:$A$21,0),MATCH(H$3,Scoreboard!$B$1:$AE$1,0))-INDEX(Scoreboard!$B$22:$AE$22,MATCH(H$3,Scoreboard!$B$1:$AE$1,0)),"")) | I10: =IF(OR($A10="",I$3=""),"",IFERROR(INDEX(Scoreboard!$B$2:$AE$21,MATCH($A10,Scoreboard!$A$2:$A$21,0),MATCH(I$3,Scoreboard!$B$1:$AE$1,0))-INDEX(Scoreboard!$B$22:$AE$22,MATCH(I$3,Scoreboard!$B$1:$AE$1,0)),"")) | ... AE10: =IF(OR($A10="",AE$3=""),"",IFERROR(INDEX(Scoreboard!$B$2:$AE$21,MATCH($A10,Scoreboard!$A$2:$A$21,0),MATCH(AE$3,Scoreboard!$B$1:$AE$1,0))-INDEX(Scoreboard!$B$22:$AE$22,MATCH(AE$3,Scoreboard!$B$1:$AE$1,0)),""))
A11: =IFERROR(Config!A9,"") | B11: =IF(OR($A11="",B$3=""),"",IFERROR(INDEX(Scoreboard!$B$2:$AE$21,MATCH($A11,Scoreboard!$A$2:$A$21,0),MATCH(B$3,Scoreboard!$B$1:$AE$1,0))-INDEX(Scoreboard!$B$22:$AE$22,MATCH(B$3,Scoreboard!$B$1:$AE$1,0)),"")) | C11: =IF(OR($A11="",C$3=""),"",IFERROR(INDEX(Scoreboard!$B$2:$AE$21,MATCH($A11,Scoreboard!$A$2:$A$21,0),MATCH(C$3,Scoreboard!$B$1:$AE$1,0))-INDEX(Scoreboard!$B$22:$AE$22,MATCH(C$3,Scoreboard!$B$1:$AE$1,0)),"")) | D11: =IF(OR($A11="",D$3=""),"",IFERROR(INDEX(Scoreboard!$B$2:$AE$21,MATCH($A11,Scoreboard!$A$2:$A$21,0),MATCH(D$3,Scoreboard!$B$1:$AE$1,0))-INDEX(Scoreboard!$B$22:$AE$22,MATCH(D$3,Scoreboard!$B$1:$AE$1,0)),"")) | E11: =IF(OR($A11="",E$3=""),"",IFERROR(INDEX(Scoreboard!$B$2:$AE$21,MATCH($A11,Scoreboard!$A$2:$A$21,0),MATCH(E$3,Scoreboard!$B$1:$AE$1,0))-INDEX(Scoreboard!$B$22:$AE$22,MATCH(E$3,Scoreboard!$B$1:$AE$1,0)),"")) | F11: =IF(OR($A11="",F$3=""),"",IFERROR(INDEX(Scoreboard!$B$2:$AE$21,MATCH($A11,Scoreboard!$A$2:$A$21,0),MATCH(F$3,Scoreboard!$B$1:$AE$1,0))-INDEX(Scoreboard!$B$22:$AE$22,MATCH(F$3,Scoreboard!$B$1:$AE$1,0)),"")) | G11: =IF(OR($A11="",G$3=""),"",IFERROR(INDEX(Scoreboard!$B$2:$AE$21,MATCH($A11,Scoreboard!$A$2:$A$21,0),MATCH(G$3,Scoreboard!$B$1:$AE$1,0))-INDEX(Scoreboard!$B$22:$AE$22,MATCH(G$3,Scoreboard!$B$1:$AE$1,0)),"")) | H11: =IF(OR($A11="",H$3=""),"",IFERROR(INDEX(Scoreboard!$B$2:$AE$21,MATCH($A11,Scoreboard!$A$2:$A$21,0),MATCH(H$3,Scoreboard!$B$1:$AE$1,0))-INDEX(Scoreboard!$B$22:$AE$22,MATCH(H$3,Scoreboard!$B$1:$AE$1,0)),"")) | I11: =IF(OR($A11="",I$3=""),"",IFERROR(INDEX(Scoreboard!$B$2:$AE$21,MATCH($A11,Scoreboard!$A$2:$A$21,0),MATCH(I$3,Scoreboard!$B$1:$AE$1,0))-INDEX(Scoreboard!$B$22:$AE$22,MATCH(I$3,Scoreboard!$B$1:$AE$1,0)),"")) | ... AE11: =IF(OR($A11="",AE$3=""),"",IFERROR(INDEX(Scoreboard!$B$2:$AE$21,MATCH($A11,Scoreboard!$A$2:$A$21,0),MATCH(AE$3,Scoreboard!$B$1:$AE$1,0))-INDEX(Scoreboard!$B$22:$AE$22,MATCH(AE$3,Scoreboard!$B$1:$AE$1,0)),""))
A12: =IFERROR(Config!A10,"") | B12: =IF(OR($A12="",B$3=""),"",IFERROR(INDEX(Scoreboard!$B$2:$AE$21,MATCH($A12,Scoreboard!$A$2:$A$21,0),MATCH(B$3,Scoreboard!$B$1:$AE$1,0))-INDEX(Scoreboard!$B$22:$AE$22,MATCH(B$3,Scoreboard!$B$1:$AE$1,0)),"")) | C12: =IF(OR($A12="",C$3=""),"",IFERROR(INDEX(Scoreboard!$B$2:$AE$21,MATCH($A12,Scoreboard!$A$2:$A$21,0),MATCH(C$3,Scoreboard!$B$1:$AE$1,0))-INDEX(Scoreboard!$B$22:$AE$22,MATCH(C$3,Scoreboard!$B$1:$AE$1,0)),"")) | D12: =IF(OR($A12="",D$3=""),"",IFERROR(INDEX(Scoreboard!$B$2:$AE$21,MATCH($A12,Scoreboard!$A$2:$A$21,0),MATCH(D$3,Scoreboard!$B$1:$AE$1,0))-INDEX(Scoreboard!$B$22:$AE$22,MATCH(D$3,Scoreboard!$B$1:$AE$1,0)),"")) | E12: =IF(OR($A12="",E$3=""),"",IFERROR(INDEX(Scoreboard!$B$2:$AE$21,MATCH($A12,Scoreboard!$A$2:$A$21,0),MATCH(E$3,Scoreboard!$B$1:$AE$1,0))-INDEX(Scoreboard!$B$22:$AE$22,MATCH(E$3,Scoreboard!$B$1:$AE$1,0)),"")) | F12: =IF(OR($A12="",F$3=""),"",IFERROR(INDEX(Scoreboard!$B$2:$AE$21,MATCH($A12,Scoreboard!$A$2:$A$21,0),MATCH(F$3,Scoreboard!$B$1:$AE$1,0))-INDEX(Scoreboard!$B$22:$AE$22,MATCH(F$3,Scoreboard!$B$1:$AE$1,0)),"")) | G12: =IF(OR($A12="",G$3=""),"",IFERROR(INDEX(Scoreboard!$B$2:$AE$21,MATCH($A12,Scoreboard!$A$2:$A$21,0),MATCH(G$3,Scoreboard!$B$1:$AE$1,0))-INDEX(Scoreboard!$B$22:$AE$22,MATCH(G$3,Scoreboard!$B$1:$AE$1,0)),"")) | H12: =IF(OR($A12="",H$3=""),"",IFERROR(INDEX(Scoreboard!$B$2:$AE$21,MATCH($A12,Scoreboard!$A$2:$A$21,0),MATCH(H$3,Scoreboard!$B$1:$AE$1,0))-INDEX(Scoreboard!$B$22:$AE$22,MATCH(H$3,Scoreboard!$B$1:$AE$1,0)),"")) | I12: =IF(OR($A12="",I$3=""),"",IFERROR(INDEX(Scoreboard!$B$2:$AE$21,MATCH($A12,Scoreboard!$A$2:$A$21,0),MATCH(I$3,Scoreboard!$B$1:$AE$1,0))-INDEX(Scoreboard!$B$22:$AE$22,MATCH(I$3,Scoreboard!$B$1:$AE$1,0)),"")) | ... AE12: =IF(OR($A12="",AE$3=""),"",IFERROR(INDEX(Scoreboard!$B$2:$AE$21,MATCH($A12,Scoreboard!$A$2:$A$21,0),MATCH(AE$3,Scoreboard!$B$1:$AE$1,0))-INDEX(Scoreboard!$B$22:$AE$22,MATCH(AE$3,Scoreboard!$B$1:$AE$1,0)),""))
